Workbook

Sheet Estimate
B1: BI Migration - Pre-sales Ballpark Estimate
B2: Fill the yellow cells. Results update instantly. For a quotable fixed price use the full v2 estimator.
B4: 1. Project settings | G4: Results
B5: Client | C5: Example Client | G5: Expected price | J5: =ExpPrice -> 496450.4
B6: Opportunity | C6: BI modernisation | G6: Ballpark range | J6: =TEXT(ExpPrice*(1+RangeLow),"$#,##0")&" to "&TEXT(ExpPrice*(1+RangeHigh),"$#,##0") -> $446,805 to $620,563
B7: Planned start date (Monday) | C7: 46391 | G7: Total effort (hours) | J7: =PlanHrs -> 6760
B8: Sprint length (weeks) | C8: 2 | G8: Duration (weeks) | J8: =DurWeeks -> 27
B9: Development team (engineers) | C9: 6 | G9: Sprints | J9: =Sprints&" x "&SprintLen&"-week" -> 8 x 2-week
B10: Assessment team (FTE) | C10: 2 | G10: Peak team (FTE) | J10: =PeakTeam -> 9
B11: Automation % (LeapLogic / accelerators) | C11: 0 | G11: Average team (FTE) | J11: =AvgTeam -> 6.2592593
B12: Contingency % | C12: 0.15 | G12: Blended rate (USD/h) | J12: =BlendedRate -> 63.860355
B13: Include project manager? | C13: Yes | G13: Planned end date | J13: =StartDate+DurWeeks*7-3 -> 46577
B14: Include AI readiness? | C14: No | G14: Status | J14: =IF(CheckFails=0,"OK - all checks pass",CheckFails&" check(s) to fix - see section 4") -> OK - all checks pass
B15: Hypercare weeks after go-live | C15: 2
B17: 2. Scope - one row per source -> target pair (most deals need one row) | S17: Workings (expand the + above column R to see)
B18: Source BI tool | C18: Target BI tool | D18: Data platform changing? | E18: Reports | F18: Avg pages per report | G18: Complexity profile | H18: % Simple | I18: % Medium | J18: % Complex | K18: % Very complex | L18: % retired / duplicates | M18: Semantic models (target) | N18: Model complexity | O18: Pair factor | P18: Report hours | Q18: Model hours | S18: Active | T18: Mix S | U18: Mix M | V18: Mix C | W18: Mix VC | X18: Src archetype | Y18: Tgt archetype | Z18: Approach share | AA18: Inventory pages | AB18: Pages to build | AC18: Analysis h | AD18: Mix flag | AE18: Platform change
B19: OBIEE | C19: Power BI | D19: Yes | E19: 300 | F19: 2 | G19: Balanced | L19: 0.2 | M19: 6 | N19: Medium | O19: =IF(S19=0,0,IFERROR(INDEX(KnownFactor,MATCH(B19&"|"&C19,KnownKey,0)),IFERROR(INDEX(ArchFactor,MATCH(X19,ArchNames,0),MATCH(Y19,ArchNames,0)),1))) -> 1 | P19: =AB19*(T19*INDEX(HrsPage,1)+U19*INDEX(HrsPage,2)+V19*INDEX(HrsPage,3)+W19*INDEX(HrsPage,4))*O19*(1+AE19*DPRep)*(1-LearnAvg)*(1-Auto*CapRep) -> 2728.53 | Q19: =S19*N(M19)*(IFERROR(INDEX(ModelHrs,MATCH(N19,ModelLevels,0)),INDEX(ModelHrs,2))*Z19*O19*(1+AE19*DPModel)*(1-Auto*CapSem)+IF(IncAI="Yes",AIHrs,0)) -> 828 | S19: =IF(AND(B19<>"",C19<>"",N(E19)>0),1,0) -> 1 | T19: =IF(G19="Custom",N(H19),IFERROR(INDEX(ProfileMix,MATCH(G19,ProfileNames,0),1),INDEX(ProfileMix,2,1))) -> 0.4 | U19: =IF(G19="Custom",N(I19),IFERROR(INDEX(ProfileMix,MATCH(G19,ProfileNames,0),2),INDEX(ProfileMix,2,2))) -> 0.4 | V19: =IF(G19="Custom",N(J19),IFERROR(INDEX(ProfileMix,MATCH(G19,ProfileNames,0),3),INDEX(ProfileMix,2,3))) -> 0.15 | W19: =IF(G19="Custom",N(K19),IFERROR(INDEX(ProfileMix,MATCH(G19,ProfileNames,0),4),INDEX(ProfileMix,2,4))) -> 0.05 | X19: =IFERROR(INDEX(ToolArch,MATCH(B19,ToolNames,0)),"Unmapped") -> Enterprise semantic-layer | Y19: =IFERROR(INDEX(ToolArch,MATCH(C19,ToolNames,0)),"Unmapped") -> Modern visual / self-service | Z19: =IFERROR(INDEX(ApproachShare,MATCH(X19,ArchNames,0),MATCH(Y19,ArchNames,0)),1) -> 1 | AA19: =S19*N(E19)*MAX(1,N(F19)) -> 600 | AB19: =AA19*(1-MIN(1,N(L19))) -> 480 | AC19: =IF(S19=1,IF(AA19<=INDEX(AnchorPages,1),INDEX(AnchorAnalysis,1),IF(AA19>=INDEX(AnchorPages,5),INDEX(AnchorAnalysis,5)+(AA19-INDEX(AnchorPages,5))*(INDEX(AnchorAnalysis,5)-INDEX(AnchorAnalysis,4))/(INDEX(AnchorPages,5)-INDEX(AnchorPages,4)),INDEX(AnchorAnalysis,MATCH(AA19,AnchorPages,1))+(AA19-INDEX(AnchorPages,MATCH(AA19,AnchorPages,1)))*(INDEX(AnchorAnalysis,MATCH(AA19,AnchorPages,1)+1)-INDEX(AnchorAnalysis,MATCH(AA19,AnchorPages,1)))/(INDEX(AnchorPages,MATCH(AA19,AnchorPages,1)+1)-INDEX(AnchorPages,MATCH(AA19,AnchorPages,1)))))*O19,0) -> 176 | AD19: =IF(AND(S19=1,OR(ABS(T19+U19+V19+W19-1)>0.001,X19="Unmapped",Y19="Unmapped")),1,0) -> 0 | AE19: =IF(AND(S19=1,D19="Yes"),1,0) -> 1
O20: =IF(S20=0,0,IFERROR(INDEX(KnownFactor,MATCH(B20&"|"&C20,KnownKey,0)),IFERROR(INDEX(ArchFactor,MATCH(X20,ArchNames,0),MATCH(Y20,ArchNames,0)),1))) -> 0 | P20: =AB20*(T20*INDEX(HrsPage,1)+U20*INDEX(HrsPage,2)+V20*INDEX(HrsPage,3)+W20*INDEX(HrsPage,4))*O20*(1+AE20*DPRep)*(1-LearnAvg)*(1-Auto*CapRep) -> 0 | Q20: =S20*N(M20)*(IFERROR(INDEX(ModelHrs,MATCH(N20,ModelLevels,0)),INDEX(ModelHrs,2))*Z20*O20*(1+AE20*DPModel)*(1-Auto*CapSem)+IF(IncAI="Yes",AIHrs,0)) -> 0 | S20: =IF(AND(B20<>"",C20<>"",N(E20)>0),1,0) -> 0 | T20: =IF(G20="Custom",N(H20),IFERROR(INDEX(ProfileMix,MATCH(G20,ProfileNames,0),1),INDEX(ProfileMix,2,1))) -> 0.4 | U20: =IF(G20="Custom",N(I20),IFERROR(INDEX(ProfileMix,MATCH(G20,ProfileNames,0),2),INDEX(ProfileMix,2,2))) -> 0.4 | V20: =IF(G20="Custom",N(J20),IFERROR(INDEX(ProfileMix,MATCH(G20,ProfileNames,0),3),INDEX(ProfileMix,2,3))) -> 0.15 | W20: =IF(G20="Custom",N(K20),IFERROR(INDEX(ProfileMix,MATCH(G20,ProfileNames,0),4),INDEX(ProfileMix,2,4))) -> 0.05 | X20: =IFERROR(INDEX(ToolArch,MATCH(B20,ToolNames,0)),"Unmapped") -> Unmapped | Y20: =IFERROR(INDEX(ToolArch,MATCH(C20,ToolNames,0)),"Unmapped") -> Unmapped | Z20: =IFERROR(INDEX(ApproachShare,MATCH(X20,ArchNames,0),MATCH(Y20,ArchNames,0)),1) -> 1 | AA20: =S20*N(E20)*MAX(1,N(F20)) -> 0 | AB20: =AA20*(1-MIN(1,N(L20))) -> 0 | AC20: =IF(S20=1,IF(AA20<=INDEX(AnchorPages,1),INDEX(AnchorAnalysis,1),IF(AA20>=INDEX(AnchorPages,5),INDEX(AnchorAnalysis,5)+(AA20-INDEX(AnchorPages,5))*(INDEX(AnchorAnalysis,5)-INDEX(AnchorAnalysis,4))/(INDEX(AnchorPages,5)-INDEX(AnchorPages,4)),INDEX(AnchorAnalysis,MATCH(AA20,AnchorPages,1))+(AA20-INDEX(AnchorPages,MATCH(AA20,AnchorPages,1)))*(INDEX(AnchorAnalysis,MATCH(AA20,AnchorPages,1)+1)-INDEX(AnchorAnalysis,MATCH(AA20,AnchorPages,1)))/(INDEX(AnchorPages,MATCH(AA20,AnchorPages,1)+1)-INDEX(AnchorPages,MATCH(AA20,AnchorPages,1)))))*O20,0) -> 0 | AD20: =IF(AND(S20=1,OR(ABS(T20+U20+V20+W20-1)>0.001,X20="Unmapped",Y20="Unmapped")),1,0) -> 0 | AE20: =IF(AND(S20=1,D20="Yes"),1,0) -> 0
O21: =IF(S21=0,0,IFERROR(INDEX(KnownFactor,MATCH(B21&"|"&C21,KnownKey,0)),IFERROR(INDEX(ArchFactor,MATCH(X21,ArchNames,0),MATCH(Y21,ArchNames,0)),1))) -> 0 | P21: =AB21*(T21*INDEX(HrsPage,1)+U21*INDEX(HrsPage,2)+V21*INDEX(HrsPage,3)+W21*INDEX(HrsPage,4))*O21*(1+AE21*DPRep)*(1-LearnAvg)*(1-Auto*CapRep) -> 0 | Q21: =S21*N(M21)*(IFERROR(INDEX(ModelHrs,MATCH(N21,ModelLevels,0)),INDEX(ModelHrs,2))*Z21*O21*(1+AE21*DPModel)*(1-Auto*CapSem)+IF(IncAI="Yes",AIHrs,0)) -> 0 | S21: =IF(AND(B21<>"",C21<>"",N(E21)>0),1,0) -> 0 | T21: =IF(G21="Custom",N(H21),IFERROR(INDEX(ProfileMix,MATCH(G21,ProfileNames,0),1),INDEX(ProfileMix,2,1))) -> 0.4 | U21: =IF(G21="Custom",N(I21),IFERROR(INDEX(ProfileMix,MATCH(G21,ProfileNames,0),2),INDEX(ProfileMix,2,2))) -> 0.4 | V21: =IF(G21="Custom",N(J21),IFERROR(INDEX(ProfileMix,MATCH(G21,ProfileNames,0),3),INDEX(ProfileMix,2,3))) -> 0.15 | W21: =IF(G21="Custom",N(K21),IFERROR(INDEX(ProfileMix,MATCH(G21,ProfileNames,0),4),INDEX(ProfileMix,2,4))) -> 0.05 | X21: =IFERROR(INDEX(ToolArch,MATCH(B21,ToolNames,0)),"Unmapped") -> Unmapped | Y21: =IFERROR(INDEX(ToolArch,MATCH(C21,ToolNames,0)),"Unmapped") -> Unmapped | Z21: =IFERROR(INDEX(ApproachShare,MATCH(X21,ArchNames,0),MATCH(Y21,ArchNames,0)),1) -> 1 | AA21: =S21*N(E21)*MAX(1,N(F21)) -> 0 | AB21: =AA21*(1-MIN(1,N(L21))) -> 0 | AC21: =IF(S21=1,IF(AA21<=INDEX(AnchorPages,1),INDEX(AnchorAnalysis,1),IF(AA21>=INDEX(AnchorPages,5),INDEX(AnchorAnalysis,5)+(AA21-INDEX(AnchorPages,5))*(INDEX(AnchorAnalysis,5)-INDEX(AnchorAnalysis,4))/(INDEX(AnchorPages,5)-INDEX(AnchorPages,4)),INDEX(AnchorAnalysis,MATCH(AA21,AnchorPages,1))+(AA21-INDEX(AnchorPages,MATCH(AA21,AnchorPages,1)))*(INDEX(AnchorAnalysis,MATCH(AA21,AnchorPages,1)+1)-INDEX(AnchorAnalysis,MATCH(AA21,AnchorPages,1)))/(INDEX(AnchorPages,MATCH(AA21,AnchorPages,1)+1)-INDEX(AnchorPages,MATCH(AA21,AnchorPages,1)))))*O21,0) -> 0 | AD21: =IF(AND(S21=1,OR(ABS(T21+U21+V21+W21-1)>0.001,X21="Unmapped",Y21="Unmapped")),1,0) -> 0 | AE21: =IF(AND(S21=1,D21="Yes"),1,0) -> 0
O22: =IF(S22=0,0,IFERROR(INDEX(KnownFactor,MATCH(B22&"|"&C22,KnownKey,0)),IFERROR(INDEX(ArchFactor,MATCH(X22,ArchNames,0),MATCH(Y22,ArchNames,0)),1))) -> 0 | P22: =AB22*(T22*INDEX(HrsPage,1)+U22*INDEX(HrsPage,2)+V22*INDEX(HrsPage,3)+W22*INDEX(HrsPage,4))*O22*(1+AE22*DPRep)*(1-LearnAvg)*(1-Auto*CapRep) -> 0 | Q22: =S22*N(M22)*(IFERROR(INDEX(ModelHrs,MATCH(N22,ModelLevels,0)),INDEX(ModelHrs,2))*Z22*O22*(1+AE22*DPModel)*(1-Auto*CapSem)+IF(IncAI="Yes",AIHrs,0)) -> 0 | S22: =IF(AND(B22<>"",C22<>"",N(E22)>0),1,0) -> 0 | T22: =IF(G22="Custom",N(H22),IFERROR(INDEX(ProfileMix,MATCH(G22,ProfileNames,0),1),INDEX(ProfileMix,2,1))) -> 0.4 | U22: =IF(G22="Custom",N(I22),IFERROR(INDEX(ProfileMix,MATCH(G22,ProfileNames,0),2),INDEX(ProfileMix,2,2))) -> 0.4 | V22: =IF(G22="Custom",N(J22),IFERROR(INDEX(ProfileMix,MATCH(G22,ProfileNames,0),3),INDEX(ProfileMix,2,3))) -> 0.15 | W22: =IF(G22="Custom",N(K22),IFERROR(INDEX(ProfileMix,MATCH(G22,ProfileNames,0),4),INDEX(ProfileMix,2,4))) -> 0.05 | X22: =IFERROR(INDEX(ToolArch,MATCH(B22,ToolNames,0)),"Unmapped") -> Unmapped | Y22: =IFERROR(INDEX(ToolArch,MATCH(C22,ToolNames,0)),"Unmapped") -> Unmapped | Z22: =IFERROR(INDEX(ApproachShare,MATCH(X22,ArchNames,0),MATCH(Y22,ArchNames,0)),1) -> 1 | AA22: =S22*N(E22)*MAX(1,N(F22)) -> 0 | AB22: =AA22*(1-MIN(1,N(L22))) -> 0 | AC22: =IF(S22=1,IF(AA22<=INDEX(AnchorPages,1),INDEX(AnchorAnalysis,1),IF(AA22>=INDEX(AnchorPages,5),INDEX(AnchorAnalysis,5)+(AA22-INDEX(AnchorPages,5))*(INDEX(AnchorAnalysis,5)-INDEX(AnchorAnalysis,4))/(INDEX(AnchorPages,5)-INDEX(AnchorPages,4)),INDEX(AnchorAnalysis,MATCH(AA22,AnchorPages,1))+(AA22-INDEX(AnchorPages,MATCH(AA22,AnchorPages,1)))*(INDEX(AnchorAnalysis,MATCH(AA22,AnchorPages,1)+1)-INDEX(AnchorAnalysis,MATCH(AA22,AnchorPages,1)))/(INDEX(AnchorPages,MATCH(AA22,AnchorPages,1)+1)-INDEX(AnchorPages,MATCH(AA22,AnchorPages,1)))))*O22,0) -> 0 | AD22: =IF(AND(S22=1,OR(ABS(T22+U22+V22+W22-1)>0.001,X22="Unmapped",Y22="Unmapped")),1,0) -> 0 | AE22: =IF(AND(S22=1,D22="Yes"),1,0) -> 0
O23: =IF(S23=0,0,IFERROR(INDEX(KnownFactor,MATCH(B23&"|"&C23,KnownKey,0)),IFERROR(INDEX(ArchFactor,MATCH(X23,ArchNames,0),MATCH(Y23,ArchNames,0)),1))) -> 0 | P23: =AB23*(T23*INDEX(HrsPage,1)+U23*INDEX(HrsPage,2)+V23*INDEX(HrsPage,3)+W23*INDEX(HrsPage,4))*O23*(1+AE23*DPRep)*(1-LearnAvg)*(1-Auto*CapRep) -> 0 | Q23: =S23*N(M23)*(IFERROR(INDEX(ModelHrs,MATCH(N23,ModelLevels,0)),INDEX(ModelHrs,2))*Z23*O23*(1+AE23*DPModel)*(1-Auto*CapSem)+IF(IncAI="Yes",AIHrs,0)) -> 0 | S23: =IF(AND(B23<>"",C23<>"",N(E23)>0),1,0) -> 0 | T23: =IF(G23="Custom",N(H23),IFERROR(INDEX(ProfileMix,MATCH(G23,ProfileNames,0),1),INDEX(ProfileMix,2,1))) -> 0.4 | U23: =IF(G23="Custom",N(I23),IFERROR(INDEX(ProfileMix,MATCH(G23,ProfileNames,0),2),INDEX(ProfileMix,2,2))) -> 0.4 | V23: =IF(G23="Custom",N(J23),IFERROR(INDEX(ProfileMix,MATCH(G23,ProfileNames,0),3),INDEX(ProfileMix,2,3))) -> 0.15 | W23: =IF(G23="Custom",N(K23),IFERROR(INDEX(ProfileMix,MATCH(G23,ProfileNames,0),4),INDEX(ProfileMix,2,4))) -> 0.05 | X23: =IFERROR(INDEX(ToolArch,MATCH(B23,ToolNames,0)),"Unmapped") -> Unmapped | Y23: =IFERROR(INDEX(ToolArch,MATCH(C23,ToolNames,0)),"Unmapped") -> Unmapped | Z23: =IFERROR(INDEX(ApproachShare,MATCH(X23,ArchNames,0),MATCH(Y23,ArchNames,0)),1) -> 1 | AA23: =S23*N(E23)*MAX(1,N(F23)) -> 0 | AB23: =AA23*(1-MIN(1,N(L23))) -> 0 | AC23: =IF(S23=1,IF(AA23<=INDEX(AnchorPages,1),INDEX(AnchorAnalysis,1),IF(AA23>=INDEX(AnchorPages,5),INDEX(AnchorAnalysis,5)+(AA23-INDEX(AnchorPages,5))*(INDEX(AnchorAnalysis,5)-INDEX(AnchorAnalysis,4))/(INDEX(AnchorPages,5)-INDEX(AnchorPages,4)),INDEX(AnchorAnalysis,MATCH(AA23,AnchorPages,1))+(AA23-INDEX(AnchorPages,MATCH(AA23,AnchorPages,1)))*(INDEX(AnchorAnalysis,MATCH(AA23,AnchorPages,1)+1)-INDEX(AnchorAnalysis,MATCH(AA23,AnchorPages,1)))/(INDEX(AnchorPages,MATCH(AA23,AnchorPages,1)+1)-INDEX(AnchorPages,MATCH(AA23,AnchorPages,1)))))*O23,0) -> 0 | AD23: =IF(AND(S23=1,OR(ABS(T23+U23+V23+W23-1)>0.001,X23="Unmapped",Y23="Unmapped")),1,0) -> 0 | AE23: =IF(AND(S23=1,D23="Yes"),1,0) -> 0
B24: % columns are used only when the profile is Custom. A new BI tool must be added on Reference with its archetype.
N25: Total | P25: =SUM(P19:P23) -> 2728.53 | Q25: =SUM(Q19:Q23) -> 828
B28: 3. Effort and cost by phase
B29: Phase | C29: Start week | D29: Weeks | E29: Avg FTE | F29: Hours | G29: Cost (USD) | H29: Basis
B30: Plan (assessment & design) | C30: =1 -> 1 | D30: =PlanWeeks -> 5 | E30: =IF(ActivePairs=0,0,CEILING(AssessHrs/(PlanWeeks*HrsWk),0.5)) -> 2 | F30: =D30*E30*HrsWk -> 400 | G30: =F30*SUMPRODUCT(MMULT(Reference!$B$61:$G$61,PlanRates)) -> 28000 | H30: Initiation + analysis (interpolated) + architecture
B31: Data model & report dev | C31: =DevStart -> 6 | D31: =DevWeeks -> 16 | E31: =IF(ActivePairs=0,0,MIN(DevTeam,CEILING(DevHrs/(DevWeeks*HrsWk),0.5))) -> 6 | F31: =D31*E31*HrsWk -> 3840 | G31: =F31*SUMPRODUCT(MMULT(Reference!$B$62:$G$62,PlanRates)) -> 227328 | H31: Models + reports + security/handover, paced in sprints
B32: Testing & validation (SIT) | C32: =DevStart+SprintLen -> 8 | D32: =DevWeeks -> 16 | E32: =IF(ActivePairs=0,0,MAX(0.5,CEILING(SITPct*DevHrs*(1-Auto*CapSIT)/(DevWeeks*HrsWk),0.5))) -> 1 | F32: =D32*E32*HrsWk -> 640 | G32: =F32*SUMPRODUCT(MMULT(Reference!$B$63:$G$63,PlanRates)) -> 36800 | H32: One sprint behind development
B33: UAT support | C33: =DevStart+2*SprintLen -> 10 | D33: =DevWeeks -> 16 | E33: =IF(ActivePairs=0,0,IF(PagesPerSprint<=UATThreshold,UATLow,UATHigh)*UATWk/SprintLen*(1-Auto*CapUAT)) -> 0.5 | F33: =D33*E33*HrsWk -> 320 | G33: =F33*SUMPRODUCT(MMULT(Reference!$B$64:$G$64,PlanRates)) -> 20608 | H33: Two sprints behind; 1-2 engineers by volume
B34: Prod deployment | C34: =DevStart+2*SprintLen -> 10 | D34: =DevWeeks -> 16 | E34: =IF(ActivePairs=0,0,DepEng*DepWk/SprintLen*(1-Auto*CapDep)) -> 0.5 | F34: =D34*E34*HrsWk -> 320 | G34: =F34*SUMPRODUCT(MMULT(Reference!$B$65:$G$65,PlanRates)) -> 19840 | H34: Deployment support each sprint
B35: Hypercare / parallel run | C35: =UATEnd+1 -> 26 | D35: =HCWk -> 2 | E35: =IF(ActivePairs=0,0,HCCrew) -> 2 | F35: =D35*E35*HrsWk -> 160 | G35: =F35*SUMPRODUCT(MMULT(Reference!$B$66:$G$66,PlanRates)) -> 10560 | H35: After final go-live
B36: Project management | C36: =1 -> 1 | D36: =DurWeeks -> 27 | E36: =IF(ActivePairs=0,0,IF(IncPM="Yes",1,0)) -> 1 | F36: =D36*E36*HrsWk -> 1080 | G36: =F36*SUMPRODUCT(MMULT(Reference!$B$67:$G$67,PlanRates)) -> 88560 | H36: Whole duration
B37: Total (from phases) | F37: =SUM(PhHours) -> 6760 | G37: =SUM(G30:G36) -> 431696
B38: Team cost (from Plan grid) | G38: =PlanCost -> 431696
B39: Contingency | G39: =PlanCost*ContPct -> 64754.4
B40: EXPECTED PRICE | G40: =PlanCost*(1+ContPct) -> 496450.4
S42: Phase workings
B43: 4. Checks | S43: ActivePairs | T43: =SUM(S19:S23) -> 1
B44: At least one scope row filled in | G44: =IF(IFERROR(ActivePairs>=1,FALSE()),"PASS","FAIL") -> PASS | S44: InvPages | T44: =SUM(AA19:AA23) -> 600
B45: Mixes total 100% and every BI tool is known | G45: =IF(IFERROR(SUM(AD19:AD23)=0,FALSE()),"PASS","FAIL") -> PASS | S45: PagesBuilt | T45: =SUM(AB19:AB23) -> 480
...

Sheet Plan
A1: ="Delivery plan - "&Client -> Delivery plan - Example Client
A2: Phase bars show FTE per week. Team rows are pre-filled from the phases - overwrite any yellow cell to hand-plan; cost follows the grid.
A4: Sprint | C4: =IF(AND(MOD(0,SprintLen)=0,1<=DurWeeks),"S"&(0/SprintLen+1),"") -> S1 | D4: =IF(AND(MOD(1,SprintLen)=0,2<=DurWeeks),"S"&(1/SprintLen+1),"") | E4: =IF(AND(MOD(2,SprintLen)=0,3<=DurWeeks),"S"&(2/SprintLen+1),"") -> S2 | F4: =IF(AND(MOD(3,SprintLen)=0,4<=DurWeeks),"S"&(3/SprintLen+1),"") | G4: =IF(AND(MOD(4,SprintLen)=0,5<=DurWeeks),"S"&(4/SprintLen+1),"") -> S3 | H4: =IF(AND(MOD(5,SprintLen)=0,6<=DurWeeks),"S"&(5/SprintLen+1),"") | I4: =IF(AND(MOD(6,SprintLen)=0,7<=DurWeeks),"S"&(6/SprintLen+1),"") -> S4 | J4: =IF(AND(MOD(7,SprintLen)=0,8<=DurWeeks),"S"&(7/SprintLen+1),"") | K4: =IF(AND(MOD(8,SprintLen)=0,9<=DurWeeks),"S"&(8/SprintLen+1),"") -> S5 | L4: =IF(AND(MOD(9,SprintLen)=0,10<=DurWeeks),"S"&(9/SprintLen+1),"") | M4: =IF(AND(MOD(10,SprintLen)=0,11<=DurWeeks),"S"&(10/SprintLen+1),"") -> S6 | N4: =IF(AND(MOD(11,SprintLen)=0,12<=DurWeeks),"S"&(11/SprintLen+1),"") | O4: =IF(AND(MOD(12,SprintLen)=0,13<=DurWeeks),"S"&(12/SprintLen+1),"") -> S7 | P4: =IF(AND(MOD(13,SprintLen)=0,14<=DurWeeks),"S"&(13/SprintLen+1),"") | Q4: =IF(AND(MOD(14,SprintLen)=0,15<=DurWeeks),"S"&(14/SprintLen+1),"") -> S8 | R4: =IF(AND(MOD(15,SprintLen)=0,16<=DurWeeks),"S"&(15/SprintLen+1),"") | S4: =IF(AND(MOD(16,SprintLen)=0,17<=DurWeeks),"S"&(16/SprintLen+1),"") -> S9 | T4: =IF(AND(MOD(17,SprintLen)=0,18<=DurWeeks),"S"&(17/SprintLen+1),"") | U4: =IF(AND(MOD(18,SprintLen)=0,19<=DurWeeks),"S"&(18/SprintLen+1),"") -> S10 | V4: =IF(AND(MOD(19,SprintLen)=0,20<=DurWeeks),"S"&(19/SprintLen+1),"") | W4: =IF(AND(MOD(20,SprintLen)=0,21<=DurWeeks),"S"&(20/SprintLen+1),"") -> S11 | X4: =IF(AND(MOD(21,SprintLen)=0,22<=DurWeeks),"S"&(21/SprintLen+1),"") | Y4: =IF(AND(MOD(22,SprintLen)=0,23<=DurWeeks),"S"&(22/SprintLen+1),"") -> S12 | Z4: =IF(AND(MOD(23,SprintLen)=0,24<=DurWeeks),"S"&(23/SprintLen+1),"") | AA4: =IF(AND(MOD(24,SprintLen)=0,25<=DurWeeks),"S"&(24/SprintLen+1),"") -> S13 | AB4: =IF(AND(MOD(25,SprintLen)=0,26<=DurWeeks),"S"&(25/SprintLen+1),"") | AC4: =IF(AND(MOD(26,SprintLen)=0,27<=DurWeeks),"S"&(26/SprintLen+1),"") -> S14 | AD4: =IF(AND(MOD(27,SprintLen)=0,28<=DurWeeks),"S"&(27/SprintLen+1),"") | AE4: =IF(AND(MOD(28,SprintLen)=0,29<=DurWeeks),"S"&(28/SprintLen+1),"") | AF4: =IF(AND(MOD(29,SprintLen)=0,30<=DurWeeks),"S"&(29/SprintLen+1),"") | AG4: =IF(AND(MOD(30,SprintLen)=0,31<=DurWeeks),"S"&(30/SprintLen+1),"") | AH4: =IF(AND(MOD(31,SprintLen)=0,32<=DurWeeks),"S"&(31/SprintLen+1),"") | AI4: =IF(AND(MOD(32,SprintLen)=0,33<=DurWeeks),"S"&(32/SprintLen+1),"") | AJ4: =IF(AND(MOD(33,SprintLen)=0,34<=DurWeeks),"S"&(33/SprintLen+1),"") | AK4: =IF(AND(MOD(34,SprintLen)=0,35<=DurWeeks),"S"&(34/SprintLen+1),"") | AL4: =IF(AND(MOD(35,SprintLen)=0,36<=DurWeeks),"S"&(35/SprintLen+1),"") | AM4: =IF(AND(MOD(36,SprintLen)=0,37<=DurWeeks),"S"&(36/SprintLen+1),"") | AN4: =IF(AND(MOD(37,SprintLen)=0,38<=DurWeeks),"S"&(37/SprintLen+1),"") | AO4: =IF(AND(MOD(38,SprintLen)=0,39<=DurWeeks),"S"&(38/SprintLen+1),"") | AP4: =IF(AND(MOD(39,SprintLen)=0,40<=DurWeeks),"S"&(39/SprintLen+1),"") | AQ4: =IF(AND(MOD(40,SprintLen)=0,41<=DurWeeks),"S"&(40/SprintLen+1),"") | AR4: =IF(AND(MOD(41,SprintLen)=0,42<=DurWeeks),"S"&(41/SprintLen+1),"") | AS4: =IF(AND(MOD(42,SprintLen)=0,43<=DurWeeks),"S"&(42/SprintLen+1),"") | AT4: =IF(AND(MOD(43,SprintLen)=0,44<=DurWeeks),"S"&(43/SprintLen+1),"") | AU4: =IF(AND(MOD(44,SprintLen)=0,45<=DurWeeks),"S"&(44/SprintLen+1),"") | AV4: =IF(AND(MOD(45,SprintLen)=0,46<=DurWeeks),"S"&(45/SprintLen+1),"") | AW4: =IF(AND(MOD(46,SprintLen)=0,47<=DurWeeks),"S"&(46/SprintLen+1),"") | AX4: =IF(AND(MOD(47,SprintLen)=0,48<=DurWeeks),"S"&(47/SprintLen+1),"") | AY4: =IF(AND(MOD(48,SprintLen)=0,49<=DurWeeks),"S"&(48/SprintLen+1),"") | AZ4: =IF(AND(MOD(49,SprintLen)=0,50<=DurWeeks),"S"&(49/SprintLen+1),"") | BA4: =IF(AND(MOD(50,SprintLen)=0,51<=DurWeeks),"S"&(50/SprintLen+1),"") | BB4: =IF(AND(MOD(51,SprintLen)=0,52<=DurWeeks),"S"&(51/SprintLen+1),"")
A5: Week | C5: Wk1 | D5: Wk2 | E5: Wk3 | F5: Wk4 | G5: Wk5 | H5: Wk6 | I5: Wk7 | J5: Wk8 | K5: Wk9 | L5: Wk10 | M5: Wk11 | N5: Wk12 | O5: Wk13 | P5: Wk14 | Q5: Wk15 | R5: Wk16 | S5: Wk17 | T5: Wk18 | U5: Wk19 | V5: Wk20 | W5: Wk21 | X5: Wk22 | Y5: Wk23 | Z5: Wk24 | AA5: Wk25 | AB5: Wk26 | AC5: Wk27 | AD5: Wk28 | AE5: Wk29 | AF5: Wk30 | AG5: Wk31 | AH5: Wk32 | AI5: Wk33 | AJ5: Wk34 | AK5: Wk35 | AL5: Wk36 | AM5: Wk37 | AN5: Wk38 | AO5: Wk39 | AP5: Wk40 | AQ5: Wk41 | AR5: Wk42 | AS5: Wk43 | AT5: Wk44 | AU5: Wk45 | AV5: Wk46 | AW5: Wk47 | AX5: Wk48 | AY5: Wk49 | AZ5: Wk50 | BA5: Wk51 | BB5: Wk52
A6: Week starting | C6: =StartDate+0*7 -> 46391 | D6: =StartDate+1*7 -> 46398 | E6: =StartDate+2*7 -> 46405 | F6: =StartDate+3*7 -> 46412 | G6: =StartDate+4*7 -> 46419 | H6: =StartDate+5*7 -> 46426 | I6: =StartDate+6*7 -> 46433 | J6: =StartDate+7*7 -> 46440 | K6: =StartDate+8*7 -> 46447 | L6: =StartDate+9*7 -> 46454 | M6: =StartDate+10*7 -> 46461 | N6: =StartDate+11*7 -> 46468 | O6: =StartDate+12*7 -> 46475 | P6: =StartDate+13*7 -> 46482 | Q6: =StartDate+14*7 -> 46489 | R6: =StartDate+15*7 -> 46496 | S6: =StartDate+16*7 -> 46503 | T6: =StartDate+17*7 -> 46510 | U6: =StartDate+18*7 -> 46517 | V6: =StartDate+19*7 -> 46524 | W6: =StartDate+20*7 -> 46531 | X6: =StartDate+21*7 -> 46538 | Y6: =StartDate+22*7 -> 46545 | Z6: =StartDate+23*7 -> 46552 | AA6: =StartDate+24*7 -> 46559 | AB6: =StartDate+25*7 -> 46566 | AC6: =StartDate+26*7 -> 46573 | AD6: =StartDate+27*7 -> 46580 | AE6: =StartDate+28*7 -> 46587 | AF6: =StartDate+29*7 -> 46594 | AG6: =StartDate+30*7 -> 46601 | AH6: =StartDate+31*7 -> 46608 | AI6: =StartDate+32*7 -> 46615 | AJ6: =StartDate+33*7 -> 46622 | AK6: =StartDate+34*7 -> 46629 | AL6: =StartDate+35*7 -> 46636 | AM6: =StartDate+36*7 -> 46643 | AN6: =StartDate+37*7 -> 46650 | AO6: =StartDate+38*7 -> 46657 | AP6: =StartDate+39*7 -> 46664 | AQ6: =StartDate+40*7 -> 46671 | AR6: =StartDate+41*7 -> 46678 | AS6: =StartDate+42*7 -> 46685 | AT6: =StartDate+43*7 -> 46692 | AU6: =StartDate+44*7 -> 46699 | AV6: =StartDate+45*7 -> 46706 | AW6: =StartDate+46*7 -> 46713 | AX6: =StartDate+47*7 -> 46720 | AY6: =StartDate+48*7 -> 46727 | AZ6: =StartDate+49*7 -> 46734 | BA6: =StartDate+50*7 -> 46741 | BB6: =StartDate+51*7 -> 46748
A7: Phases (FTE per week)
A8: Plan (assessment & design) | C8: =IF(AND(1>=INDEX(PhStart,1),1<INDEX(PhStart,1)+INDEX(PhWeeks,1)),INDEX(PhFTE,1),0) -> 2 | D8: =IF(AND(2>=INDEX(PhStart,1),2<INDEX(PhStart,1)+INDEX(PhWeeks,1)),INDEX(PhFTE,1),0) -> 2 | E8: =IF(AND(3>=INDEX(PhStart,1),3<INDEX(PhStart,1)+INDEX(PhWeeks,1)),INDEX(PhFTE,1),0) -> 2 | F8: =IF(AND(4>=INDEX(PhStart,1),4<INDEX(PhStart,1)+INDEX(PhWeeks,1)),INDEX(PhFTE,1),0) -> 2 | G8: =IF(AND(5>=INDEX(PhStart,1),5<INDEX(PhStart,1)+INDEX(PhWeeks,1)),INDEX(PhFTE,1),0) -> 2 | H8: =IF(AND(6>=INDEX(PhStart,1),6<INDEX(PhStart,1)+INDEX(PhWeeks,1)),INDEX(PhFTE,1),0) -> 0 | I8: =IF(AND(7>=INDEX(PhStart,1),7<INDEX(PhStart,1)+INDEX(PhWeeks,1)),INDEX(PhFTE,1),0) -> 0 | J8: =IF(AND(8>=INDEX(PhStart,1),8<INDEX(PhStart,1)+INDEX(PhWeeks,1)),INDEX(PhFTE,1),0) -> 0 | K8: =IF(AND(9>=INDEX(PhStart,1),9<INDEX(PhStart,1)+INDEX(PhWeeks,1)),INDEX(PhFTE,1),0) -> 0 | L8: =IF(AND(10>=INDEX(PhStart,1),10<INDEX(PhStart,1)+INDEX(PhWeeks,1)),INDEX(PhFTE,1),0) -> 0 | M8: =IF(AND(11>=INDEX(PhStart,1),11<INDEX(PhStart,1)+INDEX(PhWeeks,1)),INDEX(PhFTE,1),0) -> 0 | N8: =IF(AND(12>=INDEX(PhStart,1),12<INDEX(PhStart,1)+INDEX(PhWeeks,1)),INDEX(PhFTE,1),0) -> 0 | O8: =IF(AND(13>=INDEX(PhStart,1),13<INDEX(PhStart,1)+INDEX(PhWeeks,1)),INDEX(PhFTE,1),0) -> 0 | P8: =IF(AND(14>=INDEX(PhStart,1),14<INDEX(PhStart,1)+INDEX(PhWeeks,1)),INDEX(PhFTE,1),0) -> 0 | Q8: =IF(AND(15>=INDEX(PhStart,1),15<INDEX(PhStart,1)+INDEX(PhWeeks,1)),INDEX(PhFTE,1),0) -> 0 | R8: =IF(AND(16>=INDEX(PhStart,1),16<INDEX(PhStart,1)+INDEX(PhWeeks,1)),INDEX(PhFTE,1),0) -> 0 | S8: =IF(AND(17>=INDEX(PhStart,1),17<INDEX(PhStart,1)+INDEX(PhWeeks,1)),INDEX(PhFTE,1),0) -> 0 | T8: =IF(AND(18>=INDEX(PhStart,1),18<INDEX(PhStart,1)+INDEX(PhWeeks,1)),INDEX(PhFTE,1),0) -> 0 | U8: =IF(AND(19>=INDEX(PhStart,1),19<INDEX(PhStart,1)+INDEX(PhWeeks,1)),INDEX(PhFTE,1),0) -> 0 | V8: =IF(AND(20>=INDEX(PhStart,1),20<INDEX(PhStart,1)+INDEX(PhWeeks,1)),INDEX(PhFTE,1),0) -> 0 | W8: =IF(AND(21>=INDEX(PhStart,1),21<INDEX(PhStart,1)+INDEX(PhWeeks,1)),INDEX(PhFTE,1),0) -> 0 | X8: =IF(AND(22>=INDEX(PhStart,1),22<INDEX(PhStart,1)+INDEX(PhWeeks,1)),INDEX(PhFTE,1),0) -> 0 | Y8: =IF(AND(23>=INDEX(PhStart,1),23<INDEX(PhStart,1)+INDEX(PhWeeks,1)),INDEX(PhFTE,1),0) -> 0 | Z8: =IF(AND(24>=INDEX(PhStart,1),24<INDEX(PhStart,1)+INDEX(PhWeeks,1)),INDEX(PhFTE,1),0) -> 0 | AA8: =IF(AND(25>=INDEX(PhStart,1),25<INDEX(PhStart,1)+INDEX(PhWeeks,1)),INDEX(PhFTE,1),0) -> 0 | AB8: =IF(AND(26>=INDEX(PhStart,1),26<INDEX(PhStart,1)+INDEX(PhWeeks,1)),INDEX(PhFTE,1),0) -> 0 | AC8: =IF(AND(27>=INDEX(PhStart,1),27<INDEX(PhStart,1)+INDEX(PhWeeks,1)),INDEX(PhFTE,1),0) -> 0 | AD8: =IF(AND(28>=INDEX(PhStart,1),28<INDEX(PhStart,1)+INDEX(PhWeeks,1)),INDEX(PhFTE,1),0) -> 0 | AE8: =IF(AND(29>=INDEX(PhStart,1),29<INDEX(PhStart,1)+INDEX(PhWeeks,1)),INDEX(PhFTE,1),0) -> 0 | AF8: =IF(AND(30>=INDEX(PhStart,1),30<INDEX(PhStart,1)+INDEX(PhWeeks,1)),INDEX(PhFTE,1),0) -> 0 | AG8: =IF(AND(31>=INDEX(PhStart,1),31<INDEX(PhStart,1)+INDEX(PhWeeks,1)),INDEX(PhFTE,1),0) -> 0 | AH8: =IF(AND(32>=INDEX(PhStart,1),32<INDEX(PhStart,1)+INDEX(PhWeeks,1)),INDEX(PhFTE,1),0) -> 0 | AI8: =IF(AND(33>=INDEX(PhStart,1),33<INDEX(PhStart,1)+INDEX(PhWeeks,1)),INDEX(PhFTE,1),0) -> 0 | AJ8: =IF(AND(34>=INDEX(PhStart,1),34<INDEX(PhStart,1)+INDEX(PhWeeks,1)),INDEX(PhFTE,1),0) -> 0 | AK8: =IF(AND(35>=INDEX(PhStart,1),35<INDEX(PhStart,1)+INDEX(PhWeeks,1)),INDEX(PhFTE,1),0) -> 0 | AL8: =IF(AND(36>=INDEX(PhStart,1),36<INDEX(PhStart,1)+INDEX(PhWeeks,1)),INDEX(PhFTE,1),0) -> 0 | AM8: =IF(AND(37>=INDEX(PhStart,1),37<INDEX(PhStart,1)+INDEX(PhWeeks,1)),INDEX(PhFTE,1),0) -> 0 | AN8: =IF(AND(38>=INDEX(PhStart,1),38<INDEX(PhStart,1)+INDEX(PhWeeks,1)),INDEX(PhFTE,1),0) -> 0 | AO8: =IF(AND(39>=INDEX(PhStart,1),39<INDEX(PhStart,1)+INDEX(PhWeeks,1)),INDEX(PhFTE,1),0) -> 0 | AP8: =IF(AND(40>=INDEX(PhStart,1),40<INDEX(PhStart,1)+INDEX(PhWeeks,1)),INDEX(PhFTE,1),0) -> 0 | AQ8: =IF(AND(41>=INDEX(PhStart,1),41<INDEX(PhStart,1)+INDEX(PhWeeks,1)),INDEX(PhFTE,1),0) -> 0 | AR8: =IF(AND(42>=INDEX(PhStart,1),42<INDEX(PhStart,1)+INDEX(PhWeeks,1)),INDEX(PhFTE,1),0) -> 0 | AS8: =IF(AND(43>=INDEX(PhStart,1),43<INDEX(PhStart,1)+INDEX(PhWeeks,1)),INDEX(PhFTE,1),0) -> 0 | AT8: =IF(AND(44>=INDEX(PhStart,1),44<INDEX(PhStart,1)+INDEX(PhWeeks,1)),INDEX(PhFTE,1),0) -> 0 | AU8: =IF(AND(45>=INDEX(PhStart,1),45<INDEX(PhStart,1)+INDEX(PhWeeks,1)),INDEX(PhFTE,1),0) -> 0 | AV8: =IF(AND(46>=INDEX(PhStart,1),46<INDEX(PhStart,1)+INDEX(PhWeeks,1)),INDEX(PhFTE,1),0) -> 0 | AW8: =IF(AND(47>=INDEX(PhStart,1),47<INDEX(PhStart,1)+INDEX(PhWeeks,1)),INDEX(PhFTE,1),0) -> 0 | AX8: =IF(AND(48>=INDEX(PhStart,1),48<INDEX(PhStart,1)+INDEX(PhWeeks,1)),INDEX(PhFTE,1),0) -> 0 | AY8: =IF(AND(49>=INDEX(PhStart,1),49<INDEX(PhStart,1)+INDEX(PhWeeks,1)),INDEX(PhFTE,1),0) -> 0 | AZ8: =IF(AND(50>=INDEX(PhStart,1),50<INDEX(PhStart,1)+INDEX(PhWeeks,1)),INDEX(PhFTE,1),0) -> 0 | BA8: =IF(AND(51>=INDEX(PhStart,1),51<INDEX(PhStart,1)+INDEX(PhWeeks,1)),INDEX(PhFTE,1),0) -> 0 | BB8: =IF(AND(52>=INDEX(PhStart,1),52<INDEX(PhStart,1)+INDEX(PhWeeks,1)),INDEX(PhFTE,1),0) -> 0 | BC8: =SUM(C8:BB8) -> 10 | BD8: =BC8*HrsWk -> 400
A9: Data model & report dev | C9: =IF(AND(1>=INDEX(PhStart,2),1<INDEX(PhStart,2)+INDEX(PhWeeks,2)),INDEX(PhFTE,2),0) -> 0 | D9: =IF(AND(2>=INDEX(PhStart,2),2<INDEX(PhStart,2)+INDEX(PhWeeks,2)),INDEX(PhFTE,2),0) -> 0 | E9: =IF(AND(3>=INDEX(PhStart,2),3<INDEX(PhStart,2)+INDEX(PhWeeks,2)),INDEX(PhFTE,2),0) -> 0 | F9: =IF(AND(4>=INDEX(PhStart,2),4<INDEX(PhStart,2)+INDEX(PhWeeks,2)),INDEX(PhFTE,2),0) -> 0 | G9: =IF(AND(5>=INDEX(PhStart,2),5<INDEX(PhStart,2)+INDEX(PhWeeks,2)),INDEX(PhFTE,2),0) -> 0 | H9: =IF(AND(6>=INDEX(PhStart,2),6<INDEX(PhStart,2)+INDEX(PhWeeks,2)),INDEX(PhFTE,2),0) -> 6 | I9: =IF(AND(7>=INDEX(PhStart,2),7<INDEX(PhStart,2)+INDEX(PhWeeks,2)),INDEX(PhFTE,2),0) -> 6 | J9: =IF(AND(8>=INDEX(PhStart,2),8<INDEX(PhStart,2)+INDEX(PhWeeks,2)),INDEX(PhFTE,2),0) -> 6 | K9: =IF(AND(9>=INDEX(PhStart,2),9<INDEX(PhStart,2)+INDEX(PhWeeks,2)),INDEX(PhFTE,2),0) -> 6 | L9: =IF(AND(10>=INDEX(PhStart,2),10<INDEX(PhStart,2)+INDEX(PhWeeks,2)),INDEX(PhFTE,2),0) -> 6 | M9: =IF(AND(11>=INDEX(PhStart,2),11<INDEX(PhStart,2)+INDEX(PhWeeks,2)),INDEX(PhFTE,2),0) -> 6 | N9: =IF(AND(12>=INDEX(PhStart,2),12<INDEX(PhStart,2)+INDEX(PhWeeks,2)),INDEX(PhFTE,2),0) -> 6 | O9: =IF(AND(13>=INDEX(PhStart,2),13<INDEX(PhStart,2)+INDEX(PhWeeks,2)),INDEX(PhFTE,2),0) -> 6 | P9: =IF(AND(14>=INDEX(PhStart,2),14<INDEX(PhStart,2)+INDEX(PhWeeks,2)),INDEX(PhFTE,2),0) -> 6 | Q9: =IF(AND(15>=INDEX(PhStart,2),15<INDEX(PhStart,2)+INDEX(PhWeeks,2)),INDEX(PhFTE,2),0) -> 6 | R9: =IF(AND(16>=INDEX(PhStart,2),16<INDEX(PhStart,2)+INDEX(PhWeeks,2)),INDEX(PhFTE,2),0) -> 6 | S9: =IF(AND(17>=INDEX(PhStart,2),17<INDEX(PhStart,2)+INDEX(PhWeeks,2)),INDEX(PhFTE,2),0) -> 6 | T9: =IF(AND(18>=INDEX(PhStart,2),18<INDEX(PhStart,2)+INDEX(PhWeeks,2)),INDEX(PhFTE,2),0) -> 6 | U9: =IF(AND(19>=INDEX(PhStart,2),19<INDEX(PhStart,2)+INDEX(PhWeeks,2)),INDEX(PhFTE,2),0) -> 6 | V9: =IF(AND(20>=INDEX(PhStart,2),20<INDEX(PhStart,2)+INDEX(PhWeeks,2)),INDEX(PhFTE,2),0) -> 6 | W9: =IF(AND(21>=INDEX(PhStart,2),21<INDEX(PhStart,2)+INDEX(PhWeeks,2)),INDEX(PhFTE,2),0) -> 6 | X9: =IF(AND(22>=INDEX(PhStart,2),22<INDEX(PhStart,2)+INDEX(PhWeeks,2)),INDEX(PhFTE,2),0) -> 0 | Y9: =IF(AND(23>=INDEX(PhStart,2),23<INDEX(PhStart,2)+INDEX(PhWeeks,2)),INDEX(PhFTE,2),0) -> 0 | Z9: =IF(AND(24>=INDEX(PhStart,2),24<INDEX(PhStart,2)+INDEX(PhWeeks,2)),INDEX(PhFTE,2),0) -> 0 | AA9: =IF(AND(25>=INDEX(PhStart,2),25<INDEX(PhStart,2)+INDEX(PhWeeks,2)),INDEX(PhFTE,2),0) -> 0 | AB9: =IF(AND(26>=INDEX(PhStart,2),26<INDEX(PhStart,2)+INDEX(PhWeeks,2)),INDEX(PhFTE,2),0) -> 0 | AC9: =IF(AND(27>=INDEX(PhStart,2),27<INDEX(PhStart,2)+INDEX(PhWeeks,2)),INDEX(PhFTE,2),0) -> 0 | AD9: =IF(AND(28>=INDEX(PhStart,2),28<INDEX(PhStart,2)+INDEX(PhWeeks,2)),INDEX(PhFTE,2),0) -> 0 | AE9: =IF(AND(29>=INDEX(PhStart,2),29<INDEX(PhStart,2)+INDEX(PhWeeks,2)),INDEX(PhFTE,2),0) -> 0 | AF9: =IF(AND(30>=INDEX(PhStart,2),30<INDEX(PhStart,2)+INDEX(PhWeeks,2)),INDEX(PhFTE,2),0) -> 0 | AG9: =IF(AND(31>=INDEX(PhStart,2),31<INDEX(PhStart,2)+INDEX(PhWeeks,2)),INDEX(PhFTE,2),0) -> 0 | AH9: =IF(AND(32>=INDEX(PhStart,2),32<INDEX(PhStart,2)+INDEX(PhWeeks,2)),INDEX(PhFTE,2),0) -> 0 | AI9: =IF(AND(33>=INDEX(PhStart,2),33<INDEX(PhStart,2)+INDEX(PhWeeks,2)),INDEX(PhFTE,2),0) -> 0 | AJ9: =IF(AND(34>=INDEX(PhStart,2),34<INDEX(PhStart,2)+INDEX(PhWeeks,2)),INDEX(PhFTE,2),0) -> 0 | AK9: =IF(AND(35>=INDEX(PhStart,2),35<INDEX(PhStart,2)+INDEX(PhWeeks,2)),INDEX(PhFTE,2),0) -> 0 | AL9: =IF(AND(36>=INDEX(PhStart,2),36<INDEX(PhStart,2)+INDEX(PhWeeks,2)),INDEX(PhFTE,2),0) -> 0 | AM9: =IF(AND(37>=INDEX(PhStart,2),37<INDEX(PhStart,2)+INDEX(PhWeeks,2)),INDEX(PhFTE,2),0) -> 0 | AN9: =IF(AND(38>=INDEX(PhStart,2),38<INDEX(PhStart,2)+INDEX(PhWeeks,2)),INDEX(PhFTE,2),0) -> 0 | AO9: =IF(AND(39>=INDEX(PhStart,2),39<INDEX(PhStart,2)+INDEX(PhWeeks,2)),INDEX(PhFTE,2),0) -> 0 | AP9: =IF(AND(40>=INDEX(PhStart,2),40<INDEX(PhStart,2)+INDEX(PhWeeks,2)),INDEX(PhFTE,2),0) -> 0 | AQ9: =IF(AND(41>=INDEX(PhStart,2),41<INDEX(PhStart,2)+INDEX(PhWeeks,2)),INDEX(PhFTE,2),0) -> 0 | AR9: =IF(AND(42>=INDEX(PhStart,2),42<INDEX(PhStart,2)+INDEX(PhWeeks,2)),INDEX(PhFTE,2),0) -> 0 | AS9: =IF(AND(43>=INDEX(PhStart,2),43<INDEX(PhStart,2)+INDEX(PhWeeks,2)),INDEX(PhFTE,2),0) -> 0 | AT9: =IF(AND(44>=INDEX(PhStart,2),44<INDEX(PhStart,2)+INDEX(PhWeeks,2)),INDEX(PhFTE,2),0) -> 0 | AU9: =IF(AND(45>=INDEX(PhStart,2),45<INDEX(PhStart,2)+INDEX(PhWeeks,2)),INDEX(PhFTE,2),0) -> 0 | AV9: =IF(AND(46>=INDEX(PhStart,2),46<INDEX(PhStart,2)+INDEX(PhWeeks,2)),INDEX(PhFTE,2),0) -> 0 | AW9: =IF(AND(47>=INDEX(PhStart,2),47<INDEX(PhStart,2)+INDEX(PhWeeks,2)),INDEX(PhFTE,2),0) -> 0 | AX9: =IF(AND(48>=INDEX(PhStart,2),48<INDEX(PhStart,2)+INDEX(PhWeeks,2)),INDEX(PhFTE,2),0) -> 0 | AY9: =IF(AND(49>=INDEX(PhStart,2),49<INDEX(PhStart,2)+INDEX(PhWeeks,2)),INDEX(PhFTE,2),0) -> 0 | AZ9: =IF(AND(50>=INDEX(PhStart,2),50<INDEX(PhStart,2)+INDEX(PhWeeks,2)),INDEX(PhFTE,2),0) -> 0 | BA9: =IF(AND(51>=INDEX(PhStart,2),51<INDEX(PhStart,2)+INDEX(PhWeeks,2)),INDEX(PhFTE,2),0) -> 0 | BB9: =IF(AND(52>=INDEX(PhStart,2),52<INDEX(PhStart,2)+INDEX(PhWeeks,2)),INDEX(PhFTE,2),0) -> 0 | BC9: =SUM(C9:BB9) -> 96 | BD9: =BC9*HrsWk -> 3840
A10: Testing & validation (SIT) | C10: =IF(AND(1>=INDEX(PhStart,3),1<INDEX(PhStart,3)+INDEX(PhWeeks,3)),INDEX(PhFTE,3),0) -> 0 | D10: =IF(AND(2>=INDEX(PhStart,3),2<INDEX(PhStart,3)+INDEX(PhWeeks,3)),INDEX(PhFTE,3),0) -> 0 | E10: =IF(AND(3>=INDEX(PhStart,3),3<INDEX(PhStart,3)+INDEX(PhWeeks,3)),INDEX(PhFTE,3),0) -> 0 | F10: =IF(AND(4>=INDEX(PhStart,3),4<INDEX(PhStart,3)+INDEX(PhWeeks,3)),INDEX(PhFTE,3),0) -> 0 | G10: =IF(AND(5>=INDEX(PhStart,3),5<INDEX(PhStart,3)+INDEX(PhWeeks,3)),INDEX(PhFTE,3),0) -> 0 | H10: =IF(AND(6>=INDEX(PhStart,3),6<INDEX(PhStart,3)+INDEX(PhWeeks,3)),INDEX(PhFTE,3),0) -> 0 | I10: =IF(AND(7>=INDEX(PhStart,3),7<INDEX(PhStart,3)+INDEX(PhWeeks,3)),INDEX(PhFTE,3),0) -> 0 | J10: =IF(AND(8>=INDEX(PhStart,3),8<INDEX(PhStart,3)+INDEX(PhWeeks,3)),INDEX(PhFTE,3),0) -> 1 | K10: =IF(AND(9>=INDEX(PhStart,3),9<INDEX(PhStart,3)+INDEX(PhWeeks,3)),INDEX(PhFTE,3),0) -> 1 | L10: =IF(AND(10>=INDEX(PhStart,3),10<INDEX(PhStart,3)+INDEX(PhWeeks,3)),INDEX(PhFTE,3),0) -> 1 | M10: =IF(AND(11>=INDEX(PhStart,3),11<INDEX(PhStart,3)+INDEX(PhWeeks,3)),INDEX(PhFTE,3),0) -> 1 | N10: =IF(AND(12>=INDEX(PhStart,3),12<INDEX(PhStart,3)+INDEX(PhWeeks,3)),INDEX(PhFTE,3),0) -> 1 | O10: =IF(AND(13>=INDEX(PhStart,3),13<INDEX(PhStart,3)+INDEX(PhWeeks,3)),INDEX(PhFTE,3),0) -> 1 | P10: =IF(AND(14>=INDEX(PhStart,3),14<INDEX(PhStart,3)+INDEX(PhWeeks,3)),INDEX(PhFTE,3),0) -> 1 | Q10: =IF(AND(15>=INDEX(PhStart,3),15<INDEX(PhStart,3)+INDEX(PhWeeks,3)),INDEX(PhFTE,3),0) -> 1 | R10: =IF(AND(16>=INDEX(PhStart,3),16<INDEX(PhStart,3)+INDEX(PhWeeks,3)),INDEX(PhFTE,3),0) -> 1 | S10: =IF(AND(17>=INDEX(PhStart,3),17<INDEX(PhStart,3)+INDEX(PhWeeks,3)),INDEX(PhFTE,3),0) -> 1 | T10: =IF(AND(18>=INDEX(PhStart,3),18<INDEX(PhStart,3)+INDEX(PhWeeks,3)),INDEX(PhFTE,3),0) -> 1 | U10: =IF(AND(19>=INDEX(PhStart,3),19<INDEX(PhStart,3)+INDEX(PhWeeks,3)),INDEX(PhFTE,3),0) -> 1 | V10: =IF(AND(20>=INDEX(PhStart,3),20<INDEX(PhStart,3)+INDEX(PhWeeks,3)),INDEX(PhFTE,3),0) -> 1 | W10: =IF(AND(21>=INDEX(PhStart,3),21<INDEX(PhStart,3)+INDEX(PhWeeks,3)),INDEX(PhFTE,3),0) -> 1 | X10: =IF(AND(22>=INDEX(PhStart,3),22<INDEX(PhStart,3)+INDEX(PhWeeks,3)),INDEX(PhFTE,3),0) -> 1 | Y10: =IF(AND(23>=INDEX(PhStart,3),23<INDEX(PhStart,3)+INDEX(PhWeeks,3)),INDEX(PhFTE,3),0) -> 1 | Z10: =IF(AND(24>=INDEX(PhStart,3),24<INDEX(PhStart,3)+INDEX(PhWeeks,3)),INDEX(PhFTE,3),0) -> 0 | AA10: =IF(AND(25>=INDEX(PhStart,3),25<INDEX(PhStart,3)+INDEX(PhWeeks,3)),INDEX(PhFTE,3),0) -> 0 | AB10: =IF(AND(26>=INDEX(PhStart,3),26<INDEX(PhStart,3)+INDEX(PhWeeks,3)),INDEX(PhFTE,3),0) -> 0 | AC10: =IF(AND(27>=INDEX(PhStart,3),27<INDEX(PhStart,3)+INDEX(PhWeeks,3)),INDEX(PhFTE,3),0) -> 0 | AD10: =IF(AND(28>=INDEX(PhStart,3),28<INDEX(PhStart,3)+INDEX(PhWeeks,3)),INDEX(PhFTE,3),0) -> 0 | AE10: =IF(AND(29>=INDEX(PhStart,3),29<INDEX(PhStart,3)+INDEX(PhWeeks,3)),INDEX(PhFTE,3),0) -> 0 | AF10: =IF(AND(30>=INDEX(PhStart,3),30<INDEX(PhStart,3)+INDEX(PhWeeks,3)),INDEX(PhFTE,3),0) -> 0 | AG10: =IF(AND(31>=INDEX(PhStart,3),31<INDEX(PhStart,3)+INDEX(PhWeeks,3)),INDEX(PhFTE,3),0) -> 0 | AH10: =IF(AND(32>=INDEX(PhStart,3),32<INDEX(PhStart,3)+INDEX(PhWeeks,3)),INDEX(PhFTE,3),0) -> 0 | AI10: =IF(AND(33>=INDEX(PhStart,3),33<INDEX(PhStart,3)+INDEX(PhWeeks,3)),INDEX(PhFTE,3),0) -> 0 | AJ10: =IF(AND(34>=INDEX(PhStart,3),34<INDEX(PhStart,3)+INDEX(PhWeeks,3)),INDEX(PhFTE,3),0) -> 0 | AK10: =IF(AND(35>=INDEX(PhStart,3),35<INDEX(PhStart,3)+INDEX(PhWeeks,3)),INDEX(PhFTE,3),0) -> 0 | AL10: =IF(AND(36>=INDEX(PhStart,3),36<INDEX(PhStart,3)+INDEX(PhWeeks,3)),INDEX(PhFTE,3),0) -> 0 | AM10: =IF(AND(37>=INDEX(PhStart,3),37<INDEX(PhStart,3)+INDEX(PhWeeks,3)),INDEX(PhFTE,3),0) -> 0 | AN10: =IF(AND(38>=INDEX(PhStart,3),38<INDEX(PhStart,3)+INDEX(PhWeeks,3)),INDEX(PhFTE,3),0) -> 0 | AO10: =IF(AND(39>=INDEX(PhStart,3),39<INDEX(PhStart,3)+INDEX(PhWeeks,3)),INDEX(PhFTE,3),0) -> 0 | AP10: =IF(AND(40>=INDEX(PhStart,3),40<INDEX(PhStart,3)+INDEX(PhWeeks,3)),INDEX(PhFTE,3),0) -> 0 | AQ10: =IF(AND(41>=INDEX(PhStart,3),41<INDEX(PhStart,3)+INDEX(PhWeeks,3)),INDEX(PhFTE,3),0) -> 0 | AR10: =IF(AND(42>=INDEX(PhStart,3),42<INDEX(PhStart,3)+INDEX(PhWeeks,3)),INDEX(PhFTE,3),0) -> 0 | AS10: =IF(AND(43>=INDEX(PhStart,3),43<INDEX(PhStart,3)+INDEX(PhWeeks,3)),INDEX(PhFTE,3),0) -> 0 | AT10: =IF(AND(44>=INDEX(PhStart,3),44<INDEX(PhStart,3)+INDEX(PhWeeks,3)),INDEX(PhFTE,3),0) -> 0 | AU10: =IF(AND(45>=INDEX(PhStart,3),45<INDEX(PhStart,3)+INDEX(PhWeeks,3)),INDEX(PhFTE,3),0) -> 0 | AV10: =IF(AND(46>=INDEX(PhStart,3),46<INDEX(PhStart,3)+INDEX(PhWeeks,3)),INDEX(PhFTE,3),0) -> 0 | AW10: =IF(AND(47>=INDEX(PhStart,3),47<INDEX(PhStart,3)+INDEX(PhWeeks,3)),INDEX(PhFTE,3),0) -> 0 | AX10: =IF(AND(48>=INDEX(PhStart,3),48<INDEX(PhStart,3)+INDEX(PhWeeks,3)),INDEX(PhFTE,3),0) -> 0 | AY10: =IF(AND(49>=INDEX(PhStart,3),49<INDEX(PhStart,3)+INDEX(PhWeeks,3)),INDEX(PhFTE,3),0) -> 0 | AZ10: =IF(AND(50>=INDEX(PhStart,3),50<INDEX(PhStart,3)+INDEX(PhWeeks,3)),INDEX(PhFTE,3),0) -> 0 | BA10: =IF(AND(51>=INDEX(PhStart,3),51<INDEX(PhStart,3)+INDEX(PhWeeks,3)),INDEX(PhFTE,3),0) -> 0 | BB10: =IF(AND(52>=INDEX(PhStart,3),52<INDEX(PhStart,3)+INDEX(PhWeeks,3)),INDEX(PhFTE,3),0) -> 0 | BC10: =SUM(C10:BB10) -> 16 | BD10: =BC10*HrsWk -> 640
A11: UAT support | C11: =IF(AND(1>=INDEX(PhStart,4),1<INDEX(PhStart,4)+INDEX(PhWeeks,4)),INDEX(PhFTE,4),0) -> 0 | D11: =IF(AND(2>=INDEX(PhStart,4),2<INDEX(PhStart,4)+INDEX(PhWeeks,4)),INDEX(PhFTE,4),0) -> 0 | E11: =IF(AND(3>=INDEX(PhStart,4),3<INDEX(PhStart,4)+INDEX(PhWeeks,4)),INDEX(PhFTE,4),0) -> 0 | F11: =IF(AND(4>=INDEX(PhStart,4),4<INDEX(PhStart,4)+INDEX(PhWeeks,4)),INDEX(PhFTE,4),0) -> 0 | G11: =IF(AND(5>=INDEX(PhStart,4),5<INDEX(PhStart,4)+INDEX(PhWeeks,4)),INDEX(PhFTE,4),0) -> 0 | H11: =IF(AND(6>=INDEX(PhStart,4),6<INDEX(PhStart,4)+INDEX(PhWeeks,4)),INDEX(PhFTE,4),0) -> 0 | I11: =IF(AND(7>=INDEX(PhStart,4),7<INDEX(PhStart,4)+INDEX(PhWeeks,4)),INDEX(PhFTE,4),0) -> 0 | J11: =IF(AND(8>=INDEX(PhStart,4),8<INDEX(PhStart,4)+INDEX(PhWeeks,4)),INDEX(PhFTE,4),0) -> 0 | K11: =IF(AND(9>=INDEX(PhStart,4),9<INDEX(PhStart,4)+INDEX(PhWeeks,4)),INDEX(PhFTE,4),0) -> 0 | L11: =IF(AND(10>=INDEX(PhStart,4),10<INDEX(PhStart,4)+INDEX(PhWeeks,4)),INDEX(PhFTE,4),0) -> 0.5 | M11: =IF(AND(11>=INDEX(PhStart,4),11<INDEX(PhStart,4)+INDEX(PhWeeks,4)),INDEX(PhFTE,4),0) -> 0.5 | N11: =IF(AND(12>=INDEX(PhStart,4),12<INDEX(PhStart,4)+INDEX(PhWeeks,4)),INDEX(PhFTE,4),0) -> 0.5 | O11: =IF(AND(13>=INDEX(PhStart,4),13<INDEX(PhStart,4)+INDEX(PhWeeks,4)),INDEX(PhFTE,4),0) -> 0.5 | P11: =IF(AND(14>=INDEX(PhStart,4),14<INDEX(PhStart,4)+INDEX(PhWeeks,4)),INDEX(PhFTE,4),0) -> 0.5 | Q11: =IF(AND(15>=INDEX(PhStart,4),15<INDEX(PhStart,4)+INDEX(PhWeeks,4)),INDEX(PhFTE,4),0) -> 0.5 | R11: =IF(AND(16>=INDEX(PhStart,4),16<INDEX(PhStart,4)+INDEX(PhWeeks,4)),INDEX(PhFTE,4),0) -> 0.5 | S11: =IF(AND(17>=INDEX(PhStart,4),17<INDEX(PhStart,4)+INDEX(PhWeeks,4)),INDEX(PhFTE,4),0) -> 0.5 | T11: =IF(AND(18>=INDEX(PhStart,4),18<INDEX(PhStart,4)+INDEX(PhWeeks,4)),INDEX(PhFTE,4),0) -> 0.5 | U11: =IF(AND(19>=INDEX(PhStart,4),19<INDEX(PhStart,4)+INDEX(PhWeeks,4)),INDEX(PhFTE,4),0) -> 0.5 | V11: =IF(AND(20>=INDEX(PhStart,4),20<INDEX(PhStart,4)+INDEX(PhWeeks,4)),INDEX(PhFTE,4),0) -> 0.5 | W11: =IF(AND(21>=INDEX(PhStart,4),21<INDEX(PhStart,4)+INDEX(PhWeeks,4)),INDEX(PhFTE,4),0) -> 0.5 | X11: =IF(AND(22>=INDEX(PhStart,4),22<INDEX(PhStart,4)+INDEX(PhWeeks,4)),INDEX(PhFTE,4),0) -> 0.5 | Y11: =IF(AND(23>=INDEX(PhStart,4),23<INDEX(PhStart,4)+INDEX(PhWeeks,4)),INDEX(PhFTE,4),0) -> 0.5 | Z11: =IF(AND(24>=INDEX(PhStart,4),24<INDEX(PhStart,4)+INDEX(PhWeeks,4)),INDEX(PhFTE,4),0) -> 0.5 | AA11: =IF(AND(25>=INDEX(PhStart,4),25<INDEX(PhStart,4)+INDEX(PhWeeks,4)),INDEX(PhFTE,4),0) -> 0.5 | AB11: =IF(AND(26>=INDEX(PhStart,4),26<INDEX(PhStart,4)+INDEX(PhWeeks,4)),INDEX(PhFTE,4),0) -> 0 | AC11: =IF(AND(27>=INDEX(PhStart,4),27<INDEX(PhStart,4)+INDEX(PhWeeks,4)),INDEX(PhFTE,4),0) -> 0 | AD11: =IF(AND(28>=INDEX(PhStart,4),28<INDEX(PhStart,4)+INDEX(PhWeeks,4)),INDEX(PhFTE,4),0) -> 0 | AE11: =IF(AND(29>=INDEX(PhStart,4),29<INDEX(PhStart,4)+INDEX(PhWeeks,4)),INDEX(PhFTE,4),0) -> 0 | AF11: =IF(AND(30>=INDEX(PhStart,4),30<INDEX(PhStart,4)+INDEX(PhWeeks,4)),INDEX(PhFTE,4),0) -> 0 | AG11: =IF(AND(31>=INDEX(PhStart,4),31<INDEX(PhStart,4)+INDEX(PhWeeks,4)),INDEX(PhFTE,4),0) -> 0 | AH11: =IF(AND(32>=INDEX(PhStart,4),32<INDEX(PhStart,4)+INDEX(PhWeeks,4)),INDEX(PhFTE,4),0) -> 0 | AI11: =IF(AND(33>=INDEX(PhStart,4),33<INDEX(PhStart,4)+INDEX(PhWeeks,4)),INDEX(PhFTE,4),0) -> 0 | AJ11: =IF(AND(34>=INDEX(PhStart,4),34<INDEX(PhStart,4)+INDEX(PhWeeks,4)),INDEX(PhFTE,4),0) -> 0 | AK11: =IF(AND(35>=INDEX(PhStart,4),35<INDEX(PhStart,4)+INDEX(PhWeeks,4)),INDEX(PhFTE,4),0) -> 0 | AL11: =IF(AND(36>=INDEX(PhStart,4),36<INDEX(PhStart,4)+INDEX(PhWeeks,4)),INDEX(PhFTE,4),0) -> 0 | AM11: =IF(AND(37>=INDEX(PhStart,4),37<INDEX(PhStart,4)+INDEX(PhWeeks,4)),INDEX(PhFTE,4),0) -> 0 | AN11: =IF(AND(38>=INDEX(PhStart,4),38<INDEX(PhStart,4)+INDEX(PhWeeks,4)),INDEX(PhFTE,4),0) -> 0 | AO11: =IF(AND(39>=INDEX(PhStart,4),39<INDEX(PhStart,4)+INDEX(PhWeeks,4)),INDEX(PhFTE,4),0) -> 0 | AP11: =IF(AND(40>=INDEX(PhStart,4),40<INDEX(PhStart,4)+INDEX(PhWeeks,4)),INDEX(PhFTE,4),0) -> 0 | AQ11: =IF(AND(41>=INDEX(PhStart,4),41<INDEX(PhStart,4)+INDEX(PhWeeks,4)),INDEX(PhFTE,4),0) -> 0 | AR11: =IF(AND(42>=INDEX(PhStart,4),42<INDEX(PhStart,4)+INDEX(PhWeeks,4)),INDEX(PhFTE,4),0) -> 0 | AS11: =IF(AND(43>=INDEX(PhStart,4),43<INDEX(PhStart,4)+INDEX(PhWeeks,4)),INDEX(PhFTE,4),0) -> 0 | AT11: =IF(AND(44>=INDEX(PhStart,4),44<INDEX(PhStart,4)+INDEX(PhWeeks,4)),INDEX(PhFTE,4),0) -> 0 | AU11: =IF(AND(45>=INDEX(PhStart,4),45<INDEX(PhStart,4)+INDEX(PhWeeks,4)),INDEX(PhFTE,4),0) -> 0 | AV11: =IF(AND(46>=INDEX(PhStart,4),46<INDEX(PhStart,4)+INDEX(PhWeeks,4)),INDEX(PhFTE,4),0) -> 0 | AW11: =IF(AND(47>=INDEX(PhStart,4),47<INDEX(PhStart,4)+INDEX(PhWeeks,4)),INDEX(PhFTE,4),0) -> 0 | AX11: =IF(AND(48>=INDEX(PhStart,4),48<INDEX(PhStart,4)+INDEX(PhWeeks,4)),INDEX(PhFTE,4),0) -> 0 | AY11: =IF(AND(49>=INDEX(PhStart,4),49<INDEX(PhStart,4)+INDEX(PhWeeks,4)),INDEX(PhFTE,4),0) -> 0 | AZ11: =IF(AND(50>=INDEX(PhStart,4),50<INDEX(PhStart,4)+INDEX(PhWeeks,4)),INDEX(PhFTE,4),0) -> 0 | BA11: =IF(AND(51>=INDEX(PhStart,4),51<INDEX(PhStart,4)+INDEX(PhWeeks,4)),INDEX(PhFTE,4),0) -> 0 | BB11: =IF(AND(52>=INDEX(PhStart,4),52<INDEX(PhStart,4)+INDEX(PhWeeks,4)),INDEX(PhFTE,4),0) -> 0 | BC11: =SUM(C11:BB11) -> 8 | BD11: =BC11*HrsWk -> 320
A12: Prod deployment | C12: =IF(AND(1>=INDEX(PhStart,5),1<INDEX(PhStart,5)+INDEX(PhWeeks,5)),INDEX(PhFTE,5),0) -> 0 | D12: =IF(AND(2>=INDEX(PhStart,5),2<INDEX(PhStart,5)+INDEX(PhWeeks,5)),INDEX(PhFTE,5),0) -> 0 | E12: =IF(AND(3>=INDEX(PhStart,5),3<INDEX(PhStart,5)+INDEX(PhWeeks,5)),INDEX(PhFTE,5),0) -> 0 | F12: =IF(AND(4>=INDEX(PhStart,5),4<INDEX(PhStart,5)+INDEX(PhWeeks,5)),INDEX(PhFTE,5),0) -> 0 | G12: =IF(AND(5>=INDEX(PhStart,5),5<INDEX(PhStart,5)+INDEX(PhWeeks,5)),INDEX(PhFTE,5),0) -> 0 | H12: =IF(AND(6>=INDEX(PhStart,5),6<INDEX(PhStart,5)+INDEX(PhWeeks,5)),INDEX(PhFTE,5),0) -> 0 | I12: =IF(AND(7>=INDEX(PhStart,5),7<INDEX(PhStart,5)+INDEX(PhWeeks,5)),INDEX(PhFTE,5),0) -> 0 | J12: =IF(AND(8>=INDEX(PhStart,5),8<INDEX(PhStart,5)+INDEX(PhWeeks,5)),INDEX(PhFTE,5),0) -> 0 | K12: =IF(AND(9>=INDEX(PhStart,5),9<INDEX(PhStart,5)+INDEX(PhWeeks,5)),INDEX(PhFTE,5),0) -> 0 | L12: =IF(AND(10>=INDEX(PhStart,5),10<INDEX(PhStart,5)+INDEX(PhWeeks,5)),INDEX(PhFTE,5),0) -> 0.5 | M12: =IF(AND(11>=INDEX(PhStart,5),11<INDEX(PhStart,5)+INDEX(PhWeeks,5)),INDEX(PhFTE,5),0) -> 0.5 | N12: =IF(AND(12>=INDEX(PhStart,5),12<INDEX(PhStart,5)+INDEX(PhWeeks,5)),INDEX(PhFTE,5),0) -> 0.5 | O12: =IF(AND(13>=INDEX(PhStart,5),13<INDEX(PhStart,5)+INDEX(PhWeeks,5)),INDEX(PhFTE,5),0) -> 0.5 | P12: =IF(AND(14>=INDEX(PhStart,5),14<INDEX(PhStart,5)+INDEX(PhWeeks,5)),INDEX(PhFTE,5),0) -> 0.5 | Q12: =IF(AND(15>=INDEX(PhStart,5),15<INDEX(PhStart,5)+INDEX(PhWeeks,5)),INDEX(PhFTE,5),0) -> 0.5 | R12: =IF(AND(16>=INDEX(PhStart,5),16<INDEX(PhStart,5)+INDEX(PhWeeks,5)),INDEX(PhFTE,5),0) -> 0.5 | S12: =IF(AND(17>=INDEX(PhStart,5),17<INDEX(PhStart,5)+INDEX(PhWeeks,5)),INDEX(PhFTE,5),0) -> 0.5 | T12: =IF(AND(18>=INDEX(PhStart,5),18<INDEX(PhStart,5)+INDEX(PhWeeks,5)),INDEX(PhFTE,5),0) -> 0.5 | U12: =IF(AND(19>=INDEX(PhStart,5),19<INDEX(PhStart,5)+INDEX(PhWeeks,5)),INDEX(PhFTE,5),0) -> 0.5 | V12: =IF(AND(20>=INDEX(PhStart,5),20<INDEX(PhStart,5)+INDEX(PhWeeks,5)),INDEX(PhFTE,5),0) -> 0.5 | W12: =IF(AND(21>=INDEX(PhStart,5),21<INDEX(PhStart,5)+INDEX(PhWeeks,5)),INDEX(PhFTE,5),0) -> 0.5 | X12: =IF(AND(22>=INDEX(PhStart,5),22<INDEX(PhStart,5)+INDEX(PhWeeks,5)),INDEX(PhFTE,5),0) -> 0.5 | Y12: =IF(AND(23>=INDEX(PhStart,5),23<INDEX(PhStart,5)+INDEX(PhWeeks,5)),INDEX(PhFTE,5),0) -> 0.5 | Z12: =IF(AND(24>=INDEX(PhStart,5),24<INDEX(PhStart,5)+INDEX(PhWeeks,5)),INDEX(PhFTE,5),0) -> 0.5 | AA12: =IF(AND(25>=INDEX(PhStart,5),25<INDEX(PhStart,5)+INDEX(PhWeeks,5)),INDEX(PhFTE,5),0) -> 0.5 | AB12: =IF(AND(26>=INDEX(PhStart,5),26<INDEX(PhStart,5)+INDEX(PhWeeks,5)),INDEX(PhFTE,5),0) -> 0 | AC12: =IF(AND(27>=INDEX(PhStart,5),27<INDEX(PhStart,5)+INDEX(PhWeeks,5)),INDEX(PhFTE,5),0) -> 0 | AD12: =IF(AND(28>=INDEX(PhStart,5),28<INDEX(PhStart,5)+INDEX(PhWeeks,5)),INDEX(PhFTE,5),0) -> 0 | AE12: =IF(AND(29>=INDEX(PhStart,5),29<INDEX(PhStart,5)+INDEX(PhWeeks,5)),INDEX(PhFTE,5),0) -> 0 | AF12: =IF(AND(30>=INDEX(PhStart,5),30<INDEX(PhStart,5)+INDEX(PhWeeks,5)),INDEX(PhFTE,5),0) -> 0 | AG12: =IF(AND(31>=INDEX(PhStart,5),31<INDEX(PhStart,5)+INDEX(PhWeeks,5)),INDEX(PhFTE,5),0) -> 0 | AH12: =IF(AND(32>=INDEX(PhStart,5),32<INDEX(PhStart,5)+INDEX(PhWeeks,5)),INDEX(PhFTE,5),0) -> 0 | AI12: =IF(AND(33>=INDEX(PhStart,5),33<INDEX(PhStart,5)+INDEX(PhWeeks,5)),INDEX(PhFTE,5),0) -> 0 | AJ12: =IF(AND(34>=INDEX(PhStart,5),34<INDEX(PhStart,5)+INDEX(PhWeeks,5)),INDEX(PhFTE,5),0) -> 0 | AK12: =IF(AND(35>=INDEX(PhStart,5),35<INDEX(PhStart,5)+INDEX(PhWeeks,5)),INDEX(PhFTE,5),0) -> 0 | AL12: =IF(AND(36>=INDEX(PhStart,5),36<INDEX(PhStart,5)+INDEX(PhWeeks,5)),INDEX(PhFTE,5),0) -> 0 | AM12: =IF(AND(37>=INDEX(PhStart,5),37<INDEX(PhStart,5)+INDEX(PhWeeks,5)),INDEX(PhFTE,5),0) -> 0 | AN12: =IF(AND(38>=INDEX(PhStart,5),38<INDEX(PhStart,5)+INDEX(PhWeeks,5)),INDEX(PhFTE,5),0) -> 0 | AO12: =IF(AND(39>=INDEX(PhStart,5),39<INDEX(PhStart,5)+INDEX(PhWeeks,5)),INDEX(PhFTE,5),0) -> 0 | AP12: =IF(AND(40>=INDEX(PhStart,5),40<INDEX(PhStart,5)+INDEX(PhWeeks,5)),INDEX(PhFTE,5),0) -> 0 | AQ12: =IF(AND(41>=INDEX(PhStart,5),41<INDEX(PhStart,5)+INDEX(PhWeeks,5)),INDEX(PhFTE,5),0) -> 0 | AR12: =IF(AND(42>=INDEX(PhStart,5),42<INDEX(PhStart,5)+INDEX(PhWeeks,5)),INDEX(PhFTE,5),0) -> 0 | AS12: =IF(AND(43>=INDEX(PhStart,5),43<INDEX(PhStart,5)+INDEX(PhWeeks,5)),INDEX(PhFTE,5),0) -> 0 | AT12: =IF(AND(44>=INDEX(PhStart,5),44<INDEX(PhStart,5)+INDEX(PhWeeks,5)),INDEX(PhFTE,5),0) -> 0 | AU12: =IF(AND(45>=INDEX(PhStart,5),45<INDEX(PhStart,5)+INDEX(PhWeeks,5)),INDEX(PhFTE,5),0) -> 0 | AV12: =IF(AND(46>=INDEX(PhStart,5),46<INDEX(PhStart,5)+INDEX(PhWeeks,5)),INDEX(PhFTE,5),0) -> 0 | AW12: =IF(AND(47>=INDEX(PhStart,5),47<INDEX(PhStart,5)+INDEX(PhWeeks,5)),INDEX(PhFTE,5),0) -> 0 | AX12: =IF(AND(48>=INDEX(PhStart,5),48<INDEX(PhStart,5)+INDEX(PhWeeks,5)),INDEX(PhFTE,5),0) -> 0 | AY12: =IF(AND(49>=INDEX(PhStart,5),49<INDEX(PhStart,5)+INDEX(PhWeeks,5)),INDEX(PhFTE,5),0) -> 0 | AZ12: =IF(AND(50>=INDEX(PhStart,5),50<INDEX(PhStart,5)+INDEX(PhWeeks,5)),INDEX(PhFTE,5),0) -> 0 | BA12: =IF(AND(51>=INDEX(PhStart,5),51<INDEX(PhStart,5)+INDEX(PhWeeks,5)),INDEX(PhFTE,5),0) -> 0 | BB12: =IF(AND(52>=INDEX(PhStart,5),52<INDEX(PhStart,5)+INDEX(PhWeeks,5)),INDEX(PhFTE,5),0) -> 0 | BC12: =SUM(C12:BB12) -> 8 | BD12: =BC12*HrsWk -> 320
A13: Hypercare / parallel run | C13: =IF(AND(1>=INDEX(PhStart,6),1<INDEX(PhStart,6)+INDEX(PhWeeks,6)),INDEX(PhFTE,6),0) -> 0 | D13: =IF(AND(2>=INDEX(PhStart,6),2<INDEX(PhStart,6)+INDEX(PhWeeks,6)),INDEX(PhFTE,6),0) -> 0 | E13: =IF(AND(3>=INDEX(PhStart,6),3<INDEX(PhStart,6)+INDEX(PhWeeks,6)),INDEX(PhFTE,6),0) -> 0 | F13: =IF(AND(4>=INDEX(PhStart,6),4<INDEX(PhStart,6)+INDEX(PhWeeks,6)),INDEX(PhFTE,6),0) -> 0 | G13: =IF(AND(5>=INDEX(PhStart,6),5<INDEX(PhStart,6)+INDEX(PhWeeks,6)),INDEX(PhFTE,6),0) -> 0 | H13: =IF(AND(6>=INDEX(PhStart,6),6<INDEX(PhStart,6)+INDEX(PhWeeks,6)),INDEX(PhFTE,6),0) -> 0 | I13: =IF(AND(7>=INDEX(PhStart,6),7<INDEX(PhStart,6)+INDEX(PhWeeks,6)),INDEX(PhFTE,6),0) -> 0 | J13: =IF(AND(8>=INDEX(PhStart,6),8<INDEX(PhStart,6)+INDEX(PhWeeks,6)),INDEX(PhFTE,6),0) -> 0 | K13: =IF(AND(9>=INDEX(PhStart,6),9<INDEX(PhStart,6)+INDEX(PhWeeks,6)),INDEX(PhFTE,6),0) -> 0 | L13: =IF(AND(10>=INDEX(PhStart,6),10<INDEX(PhStart,6)+INDEX(PhWeeks,6)),INDEX(PhFTE,6),0) -> 0 | M13: =IF(AND(11>=INDEX(PhStart,6),11<INDEX(PhStart,6)+INDEX(PhWeeks,6)),INDEX(PhFTE,6),0) -> 0 | N13: =IF(AND(12>=INDEX(PhStart,6),12<INDEX(PhStart,6)+INDEX(PhWeeks,6)),INDEX(PhFTE,6),0) -> 0 | O13: =IF(AND(13>=INDEX(PhStart,6),13<INDEX(PhStart,6)+INDEX(PhWeeks,6)),INDEX(PhFTE,6),0) -> 0 | P13: =IF(AND(14>=INDEX(PhStart,6),14<INDEX(PhStart,6)+INDEX(PhWeeks,6)),INDEX(PhFTE,6),0) -> 0 | Q13: =IF(AND(15>=INDEX(PhStart,6),15<INDEX(PhStart,6)+INDEX(PhWeeks,6)),INDEX(PhFTE,6),0) -> 0 | R13: =IF(AND(16>=INDEX(PhStart,6),16<INDEX(PhStart,6)+INDEX(PhWeeks,6)),INDEX(PhFTE,6),0) -> 0 | S13: =IF(AND(17>=INDEX(PhStart,6),17<INDEX(PhStart,6)+INDEX(PhWeeks,6)),INDEX(PhFTE,6),0) -> 0 | T13: =IF(AND(18>=INDEX(PhStart,6),18<INDEX(PhStart,6)+INDEX(PhWeeks,6)),INDEX(PhFTE,6),0) -> 0 | U13: =IF(AND(19>=INDEX(PhStart,6),19<INDEX(PhStart,6)+INDEX(PhWeeks,6)),INDEX(PhFTE,6),0) -> 0 | V13: =IF(AND(20>=INDEX(PhStart,6),20<INDEX(PhStart,6)+INDEX(PhWeeks,6)),INDEX(PhFTE,6),0) -> 0 | W13: =IF(AND(21>=INDEX(PhStart,6),21<INDEX(PhStart,6)+INDEX(PhWeeks,6)),INDEX(PhFTE,6),0) -> 0 | X13: =IF(AND(22>=INDEX(PhStart,6),22<INDEX(PhStart,6)+INDEX(PhWeeks,6)),INDEX(PhFTE,6),0) -> 0 | Y13: =IF(AND(23>=INDEX(PhStart,6),23<INDEX(PhStart,6)+INDEX(PhWeeks,6)),INDEX(PhFTE,6),0) -> 0 | Z13: =IF(AND(24>=INDEX(PhStart,6),24<INDEX(PhStart,6)+INDEX(PhWeeks,6)),INDEX(PhFTE,6),0) -> 0 | AA13: =IF(AND(25>=INDEX(PhStart,6),25<INDEX(PhStart,6)+INDEX(PhWeeks,6)),INDEX(PhFTE,6),0) -> 0 | AB13: =IF(AND(26>=INDEX(PhStart,6),26<INDEX(PhStart,6)+INDEX(PhWeeks,6)),INDEX(PhFTE,6),0) -> 2 | AC13: =IF(AND(27>=INDEX(PhStart,6),27<INDEX(PhStart,6)+INDEX(PhWeeks,6)),INDEX(PhFTE,6),0) -> 2 | AD13: =IF(AND(28>=INDEX(PhStart,6),28<INDEX(PhStart,6)+INDEX(PhWeeks,6)),INDEX(PhFTE,6),0) -> 0 | AE13: =IF(AND(29>=INDEX(PhStart,6),29<INDEX(PhStart,6)+INDEX(PhWeeks,6)),INDEX(PhFTE,6),0) -> 0 | AF13: =IF(AND(30>=INDEX(PhStart,6),30<INDEX(PhStart,6)+INDEX(PhWeeks,6)),INDEX(PhFTE,6),0) -> 0 | AG13: =IF(AND(31>=INDEX(PhStart,6),31<INDEX(PhStart,6)+INDEX(PhWeeks,6)),INDEX(PhFTE,6),0) -> 0 | AH13: =IF(AND(32>=INDEX(PhStart,6),32<INDEX(PhStart,6)+INDEX(PhWeeks,6)),INDEX(PhFTE,6),0) -> 0 | AI13: =IF(AND(33>=INDEX(PhStart,6),33<INDEX(PhStart,6)+INDEX(PhWeeks,6)),INDEX(PhFTE,6),0) -> 0 | AJ13: =IF(AND(34>=INDEX(PhStart,6),34<INDEX(PhStart,6)+INDEX(PhWeeks,6)),INDEX(PhFTE,6),0) -> 0 | AK13: =IF(AND(35>=INDEX(PhStart,6),35<INDEX(PhStart,6)+INDEX(PhWeeks,6)),INDEX(PhFTE,6),0) -> 0 | AL13: =IF(AND(36>=INDEX(PhStart,6),36<INDEX(PhStart,6)+INDEX(PhWeeks,6)),INDEX(PhFTE,6),0) -> 0 | AM13: =IF(AND(37>=INDEX(PhStart,6),37<INDEX(PhStart,6)+INDEX(PhWeeks,6)),INDEX(PhFTE,6),0) -> 0 | AN13: =IF(AND(38>=INDEX(PhStart,6),38<INDEX(PhStart,6)+INDEX(PhWeeks,6)),INDEX(PhFTE,6),0) -> 0 | AO13: =IF(AND(39>=INDEX(PhStart,6),39<INDEX(PhStart,6)+INDEX(PhWeeks,6)),INDEX(PhFTE,6),0) -> 0 | AP13: =IF(AND(40>=INDEX(PhStart,6),40<INDEX(PhStart,6)+INDEX(PhWeeks,6)),INDEX(PhFTE,6),0) -> 0 | AQ13: =IF(AND(41>=INDEX(PhStart,6),41<INDEX(PhStart,6)+INDEX(PhWeeks,6)),INDEX(PhFTE,6),0) -> 0 | AR13: =IF(AND(42>=INDEX(PhStart,6),42<INDEX(PhStart,6)+INDEX(PhWeeks,6)),INDEX(PhFTE,6),0) -> 0 | AS13: =IF(AND(43>=INDEX(PhStart,6),43<INDEX(PhStart,6)+INDEX(PhWeeks,6)),INDEX(PhFTE,6),0) -> 0 | AT13: =IF(AND(44>=INDEX(PhStart,6),44<INDEX(PhStart,6)+INDEX(PhWeeks,6)),INDEX(PhFTE,6),0) -> 0 | AU13: =IF(AND(45>=INDEX(PhStart,6),45<INDEX(PhStart,6)+INDEX(PhWeeks,6)),INDEX(PhFTE,6),0) -> 0 | AV13: =IF(AND(46>=INDEX(PhStart,6),46<INDEX(PhStart,6)+INDEX(PhWeeks,6)),INDEX(PhFTE,6),0) -> 0 | AW13: =IF(AND(47>=INDEX(PhStart,6),47<INDEX(PhStart,6)+INDEX(PhWeeks,6)),INDEX(PhFTE,6),0) -> 0 | AX13: =IF(AND(48>=INDEX(PhStart,6),48<INDEX(PhStart,6)+INDEX(PhWeeks,6)),INDEX(PhFTE,6),0) -> 0 | AY13: =IF(AND(49>=INDEX(PhStart,6),49<INDEX(PhStart,6)+INDEX(PhWeeks,6)),INDEX(PhFTE,6),0) -> 0 | AZ13: =IF(AND(50>=INDEX(PhStart,6),50<INDEX(PhStart,6)+INDEX(PhWeeks,6)),INDEX(PhFTE,6),0) -> 0 | BA13: =IF(AND(51>=INDEX(PhStart,6),51<INDEX(PhStart,6)+INDEX(PhWeeks,6)),INDEX(PhFTE,6),0) -> 0 | BB13: =IF(AND(52>=INDEX(PhStart,6),52<INDEX(PhStart,6)+INDEX(PhWeeks,6)),INDEX(PhFTE,6),0) -> 0 | BC13: =SUM(C13:BB13) -> 4 | BD13: =BC13*HrsWk -> 160
A14: Project management | C14: =IF(AND(1>=INDEX(PhStart,7),1<INDEX(PhStart,7)+INDEX(PhWeeks,7)),INDEX(PhFTE,7),0) -> 1 | D14: =IF(AND(2>=INDEX(PhStart,7),2<INDEX(PhStart,7)+INDEX(PhWeeks,7)),INDEX(PhFTE,7),0) -> 1 | E14: =IF(AND(3>=INDEX(PhStart,7),3<INDEX(PhStart,7)+INDEX(PhWeeks,7)),INDEX(PhFTE,7),0) -> 1 | F14: =IF(AND(4>=INDEX(PhStart,7),4<INDEX(PhStart,7)+INDEX(PhWeeks,7)),INDEX(PhFTE,7),0) -> 1 | G14: =IF(AND(5>=INDEX(PhStart,7),5<INDEX(PhStart,7)+INDEX(PhWeeks,7)),INDEX(PhFTE,7),0) -> 1 | H14: =IF(AND(6>=INDEX(PhStart,7),6<INDEX(PhStart,7)+INDEX(PhWeeks,7)),INDEX(PhFTE,7),0) -> 1 | I14: =IF(AND(7>=INDEX(PhStart,7),7<INDEX(PhStart,7)+INDEX(PhWeeks,7)),INDEX(PhFTE,7),0) -> 1 | J14: =IF(AND(8>=INDEX(PhStart,7),8<INDEX(PhStart,7)+INDEX(PhWeeks,7)),INDEX(PhFTE,7),0) -> 1 | K14: =IF(AND(9>=INDEX(PhStart,7),9<INDEX(PhStart,7)+INDEX(PhWeeks,7)),INDEX(PhFTE,7),0) -> 1 | L14: =IF(AND(10>=INDEX(PhStart,7),10<INDEX(PhStart,7)+INDEX(PhWeeks,7)),INDEX(PhFTE,7),0) -> 1 | M14: =IF(AND(11>=INDEX(PhStart,7),11<INDEX(PhStart,7)+INDEX(PhWeeks,7)),INDEX(PhFTE,7),0) -> 1 | N14: =IF(AND(12>=INDEX(PhStart,7),12<INDEX(PhStart,7)+INDEX(PhWeeks,7)),INDEX(PhFTE,7),0) -> 1 | O14: =IF(AND(13>=INDEX(PhStart,7),13<INDEX(PhStart,7)+INDEX(PhWeeks,7)),INDEX(PhFTE,7),0) -> 1 | P14: =IF(AND(14>=INDEX(PhStart,7),14<INDEX(PhStart,7)+INDEX(PhWeeks,7)),INDEX(PhFTE,7),0) -> 1 | Q14: =IF(AND(15>=INDEX(PhStart,7),15<INDEX(PhStart,7)+INDEX(PhWeeks,7)),INDEX(PhFTE,7),0) -> 1 | R14: =IF(AND(16>=INDEX(PhStart,7),16<INDEX(PhStart,7)+INDEX(PhWeeks,7)),INDEX(PhFTE,7),0) -> 1 | S14: =IF(AND(17>=INDEX(PhStart,7),17<INDEX(PhStart,7)+INDEX(PhWeeks,7)),INDEX(PhFTE,7),0) -> 1 | T14: =IF(AND(18>=INDEX(PhStart,7),18<INDEX(PhStart,7)+INDEX(PhWeeks,7)),INDEX(PhFTE,7),0) -> 1 | U14: =IF(AND(19>=INDEX(PhStart,7),19<INDEX(PhStart,7)+INDEX(PhWeeks,7)),INDEX(PhFTE,7),0) -> 1 | V14: =IF(AND(20>=INDEX(PhStart,7),20<INDEX(PhStart,7)+INDEX(PhWeeks,7)),INDEX(PhFTE,7),0) -> 1 | W14: =IF(AND(21>=INDEX(PhStart,7),21<INDEX(PhStart,7)+INDEX(PhWeeks,7)),INDEX(PhFTE,7),0) -> 1 | X14: =IF(AND(22>=INDEX(PhStart,7),22<INDEX(PhStart,7)+INDEX(PhWeeks,7)),INDEX(PhFTE,7),0) -> 1 | Y14: =IF(AND(23>=INDEX(PhStart,7),23<INDEX(PhStart,7)+INDEX(PhWeeks,7)),INDEX(PhFTE,7),0) -> 1 | Z14: =IF(AND(24>=INDEX(PhStart,7),24<INDEX(PhStart,7)+INDEX(PhWeeks,7)),INDEX(PhFTE,7),0) -> 1 | AA14: =IF(AND(25>=INDEX(PhStart,7),25<INDEX(PhStart,7)+INDEX(PhWeeks,7)),INDEX(PhFTE,7),0) -> 1 | AB14: =IF(AND(26>=INDEX(PhStart,7),26<INDEX(PhStart,7)+INDEX(PhWeeks,7)),INDEX(PhFTE,7),0) -> 1 | AC14: =IF(AND(27>=INDEX(PhStart,7),27<INDEX(PhStart,7)+INDEX(PhWeeks,7)),INDEX(PhFTE,7),0) -> 1 | AD14: =IF(AND(28>=INDEX(PhStart,7),28<INDEX(PhStart,7)+INDEX(PhWeeks,7)),INDEX(PhFTE,7),0) -> 0 | AE14: =IF(AND(29>=INDEX(PhStart,7),29<INDEX(PhStart,7)+INDEX(PhWeeks,7)),INDEX(PhFTE,7),0) -> 0 | AF14: =IF(AND(30>=INDEX(PhStart,7),30<INDEX(PhStart,7)+INDEX(PhWeeks,7)),INDEX(PhFTE,7),0) -> 0 | AG14: =IF(AND(31>=INDEX(PhStart,7),31<INDEX(PhStart,7)+INDEX(PhWeeks,7)),INDEX(PhFTE,7),0) -> 0 | AH14: =IF(AND(32>=INDEX(PhStart,7),32<INDEX(PhStart,7)+INDEX(PhWeeks,7)),INDEX(PhFTE,7),0) -> 0 | AI14: =IF(AND(33>=INDEX(PhStart,7),33<INDEX(PhStart,7)+INDEX(PhWeeks,7)),INDEX(PhFTE,7),0) -> 0 | AJ14: =IF(AND(34>=INDEX(PhStart,7),34<INDEX(PhStart,7)+INDEX(PhWeeks,7)),INDEX(PhFTE,7),0) -> 0 | AK14: =IF(AND(35>=INDEX(PhStart,7),35<INDEX(PhStart,7)+INDEX(PhWeeks,7)),INDEX(PhFTE,7),0) -> 0 | AL14: =IF(AND(36>=INDEX(PhStart,7),36<INDEX(PhStart,7)+INDEX(PhWeeks,7)),INDEX(PhFTE,7),0) -> 0 | AM14: =IF(AND(37>=INDEX(PhStart,7),37<INDEX(PhStart,7)+INDEX(PhWeeks,7)),INDEX(PhFTE,7),0) -> 0 | AN14: =IF(AND(38>=INDEX(PhStart,7),38<INDEX(PhStart,7)+INDEX(PhWeeks,7)),INDEX(PhFTE,7),0) -> 0 | AO14: =IF(AND(39>=INDEX(PhStart,7),39<INDEX(PhStart,7)+INDEX(PhWeeks,7)),INDEX(PhFTE,7),0) -> 0 | AP14: =IF(AND(40>=INDEX(PhStart,7),40<INDEX(PhStart,7)+INDEX(PhWeeks,7)),INDEX(PhFTE,7),0) -> 0 | AQ14: =IF(AND(41>=INDEX(PhStart,7),41<INDEX(PhStart,7)+INDEX(PhWeeks,7)),INDEX(PhFTE,7),0) -> 0 | AR14: =IF(AND(42>=INDEX(PhStart,7),42<INDEX(PhStart,7)+INDEX(PhWeeks,7)),INDEX(PhFTE,7),0) -> 0 | AS14: =IF(AND(43>=INDEX(PhStart,7),43<INDEX(PhStart,7)+INDEX(PhWeeks,7)),INDEX(PhFTE,7),0) -> 0 | AT14: =IF(AND(44>=INDEX(PhStart,7),44<INDEX(PhStart,7)+INDEX(PhWeeks,7)),INDEX(PhFTE,7),0) -> 0 | AU14: =IF(AND(45>=INDEX(PhStart,7),45<INDEX(PhStart,7)+INDEX(PhWeeks,7)),INDEX(PhFTE,7),0) -> 0 | AV14: =IF(AND(46>=INDEX(PhStart,7),46<INDEX(PhStart,7)+INDEX(PhWeeks,7)),INDEX(PhFTE,7),0) -> 0 | AW14: =IF(AND(47>=INDEX(PhStart,7),47<INDEX(PhStart,7)+INDEX(PhWeeks,7)),INDEX(PhFTE,7),0) -> 0 | AX14: =IF(AND(48>=INDEX(PhStart,7),48<INDEX(PhStart,7)+INDEX(PhWeeks,7)),INDEX(PhFTE,7),0) -> 0 | AY14: =IF(AND(49>=INDEX(PhStart,7),49<INDEX(PhStart,7)+INDEX(PhWeeks,7)),INDEX(PhFTE,7),0) -> 0 | AZ14: =IF(AND(50>=INDEX(PhStart,7),50<INDEX(PhStart,7)+INDEX(PhWeeks,7)),INDEX(PhFTE,7),0) -> 0 | BA14: =IF(AND(51>=INDEX(PhStart,7),51<INDEX(PhStart,7)+INDEX(PhWeeks,7)),INDEX(PhFTE,7),0) -> 0 | BB14: =IF(AND(52>=INDEX(PhStart,7),52<INDEX(PhStart,7)+INDEX(PhWeeks,7)),INDEX(PhFTE,7),0) -> 0 | BC14: =SUM(C14:BB14) -> 27 | BD14: =BC14*HrsWk -> 1080
A15: Total FTE | C15: =SUM(C8:C14) -> 3 | D15: =SUM(D8:D14) -> 3 | E15: =SUM(E8:E14) -> 3 | F15: =SUM(F8:F14) -> 3 | G15: =SUM(G8:G14) -> 3 | H15: =SUM(H8:H14) -> 7 | I15: =SUM(I8:I14) -> 7 | J15: =SUM(J8:J14) -> 8 | ... BB15: =SUM(BB8:BB14) -> 0
A17: Team | B17: Rate (USD/h) | C17: Wk1 | D17: Wk2 | E17: Wk3 | F17: Wk4 | G17: Wk5 | H17: Wk6 | I17: Wk7 | J17: Wk8 | K17: Wk9 | L17: Wk10 | M17: Wk11 | N17: Wk12 | O17: Wk13 | P17: Wk14 | Q17: Wk15 | R17: Wk16 | S17: Wk17 | T17: Wk18 | U17: Wk19 | V17: Wk20 | W17: Wk21 | X17: Wk22 | Y17: Wk23 | Z17: Wk24 | AA17: Wk25 | AB17: Wk26 | AC17: Wk27 | AD17: Wk28 | AE17: Wk29 | AF17: Wk30 | AG17: Wk31 | AH17: Wk32 | AI17: Wk33 | AJ17: Wk34 | AK17: Wk35 | AL17: Wk36 | AM17: Wk37 | AN17: Wk38 | AO17: Wk39 | AP17: Wk40 | AQ17: Wk41 | AR17: Wk42 | AS17: Wk43 | AT17: Wk44 | AU17: Wk45 | AV17: Wk46 | AW17: Wk47 | AX17: Wk48 | AY17: Wk49 | AZ17: Wk50 | BA17: Wk51 | BB17: Wk52 | BC17: Person-weeks | BD17: Hours | BE17: Cost (USD)
A18: BI Architect | B18: =IFERROR(INDEX(RateVals,MATCH("Architect II | G11 | India",RateKeys,0)),0) -> 70 | C18: =SUMPRODUCT(C$8:C$14,Reference!$B$61:$B$67) -> 1 | D18: =SUMPRODUCT(D$8:D$14,Reference!$B$61:$B$67) -> 1 | E18: =SUMPRODUCT(E$8:E$14,Reference!$B$61:$B$67) -> 1 | F18: =SUMPRODUCT(F$8:F$14,Reference!$B$61:$B$67) -> 1 | G18: =SUMPRODUCT(G$8:G$14,Reference!$B$61:$B$67) -> 1 | H18: =SUMPRODUCT(H$8:H$14,Reference!$B$61:$B$67) -> 0.6 | I18: =SUMPRODUCT(I$8:I$14,Reference!$B$61:$B$67) -> 0.6 | J18: =SUMPRODUCT(J$8:J$14,Reference!$B$61:$B$67) -> 0.6 | ... BB18: =SUMPRODUCT(BB$8:BB$14,Reference!$B$61:$B$67) -> 0 | BC18: =SUM(C18:BB18) -> 14.6 | BD18: =BC18*HrsWk -> 584 | BE18: =BD18*B18 -> 40880
A19: Lead BI Engineer | B19: =IFERROR(INDEX(RateVals,MATCH("Lead II | G11 | India",RateKeys,0)),0) -> 70 | C19: =SUMPRODUCT(C$8:C$14,Reference!$C$61:$C$67) -> 1 | D19: =SUMPRODUCT(D$8:D$14,Reference!$C$61:$C$67) -> 1 | E19: =SUMPRODUCT(E$8:E$14,Reference!$C$61:$C$67) -> 1 | F19: =SUMPRODUCT(F$8:F$14,Reference!$C$61:$C$67) -> 1 | G19: =SUMPRODUCT(G$8:G$14,Reference!$C$61:$C$67) -> 1 | H19: =SUMPRODUCT(H$8:H$14,Reference!$C$61:$C$67) -> 0.9 | I19: =SUMPRODUCT(I$8:I$14,Reference!$C$61:$C$67) -> 0.9 | J19: =SUMPRODUCT(J$8:J$14,Reference!$C$61:$C$67) -> 0.9 | ... BB19: =SUMPRODUCT(BB$8:BB$14,Reference!$C$61:$C$67) -> 0 | BC19: =SUM(C19:BB19) -> 23.8 | BD19: =BC19*HrsWk -> 952 | BE19: =BD19*B19 -> 66640
