Workbook

Sheet Guide
A1: BI Migration Estimator v2
A2: Quotable fixed-price estimate for BI report and semantic-model migrations.
B4: How to use
B5: 1. Setup | C5: Enter engagement details, iteration length, team and ramp settings, SIT/UAT/deployment cadence, automation % by phase and cost mode.
B6: 2. Scope | C6: One row per migration pair. Pick or type the source and target BI tool and data platform, then inventory, complexity mix, rationalisation, semantic models, security and AI readiness. Example rows are provided - overwrite them.
B7: 3. Risks | C7: List named risks with impact hours and probability. Expected hours become the risk reserve.
B8: 4. Roles | C8: Choose the rate-card row for each plan role and adjust the role mix per phase (each row totals 100%).
B9: 5. Checks | C9: Fix every FAIL. The Summary banner turns green only when all checks pass.
B10: 6. Summary | C10: Read the price, effort, duration, team and dates. Print Summary and Assumptions for the proposal.
B11: 7. Plan | C11: Review the weekly headcount. Use the manual adjustment rows to reshape the team; the reconciliation check flags gaps over the tolerance.
B13: Colour key
B14: Input | C14: Yellow cell with blue text: editable input (all other cells are locked; sheets are protected without a password).
B15: Calculated | C15: Black text: formula - do not overwrite.
B16: Header | C16: Table header.
B18: Tabs
B19: Summary | C19: One-page quotable view.
B20: Setup | C20: Engagement-wide inputs.
B21: Scope | C21: Migration pairs (up to 20).
B22: Risks | C22: Risk register.
B23: Roles | C23: Plan roles, rate selection and role mix by phase.
B24: Rates | C24: Rate card (bill rates, USD/h).
B25: Lists | C25: Tools, archetypes, known pair factors, data platforms.
B26: Baseline | C26: Reference values with status: Carried / Reshaped / New proposal / User decision.
B27: Effort | C27: Hours per pair and phase; programme-level hours; totals.
B28: Schedule | C28: Iterations, waves, phase windows, milestones.
B29: Plan | C29: Weekly hours and headcount by role.
B30: Cost | C30: Cost by role and phase; price build-up; payment milestones.
... B34: ChangeLog | C34: Version history.
B36: Method
C37: Report development = full-effort pages x mix-weighted hours per page x pair factor x data-platform uplift x report-type factor x (1 - learning gain) x (1 - automation saving), plus derived and merge hours.
C38: Semantic models = target models x mix-weighted model hours x approach share x pair factor x platform uplift, plus consolidation hours, less automation saving.
C39: Iterations: report hours / (peak team x hours per week) plus half the ramp weeks, divided by iteration length (or fixed directly).
C40: SIT runs one iteration behind development and UAT two behind; both are sized per iteration (crew x weeks), plus a final regression and UAT cycle.
C41: Automation saving per phase = automation % x automatable cap, so automation never removes the review and validation work.
C42: No step tiers: initiation and analysis interpolate between the old calculator's tier values.

Sheet Summary
B1: ="BI Migration Estimate - "&Client -> BI Migration Estimate - Example Client
B2: =Opportunity&" | "&EstVersion&" | "&TEXT(EstDate,"dd-mmm-yyyy")&" | Start "&TEXT(StartDate,"dd-mmm-yyyy")&" | All money in "&Currency -> BI modernisation programme | v2.0-draft | 13-Oct-2026 | Start 04-Jan-2027 | All money in USD
B4: =IF(FailCount=0,"VALID ESTIMATE - all checks pass","NOT VALID - "&FailCount&" check(s) failing: see the Checks tab") -> VALID ESTIMATE - all checks pass
B6: Fixed price | D6: Total effort (hours) | H6: Duration (working weeks) | J6: Planned end date
B7: =FixedPrice -> 1069220.9 | D7: =TotalHrs -> 17010.763 | H7: =DurationWeeks -> 36 | J7: =EndDate -> 46654
B9: Development iterations | D9: Releases | H9: Peak team (FTE) | J9: Average team (FTE)
B10: =IterCount&" x "&IterLen&" wk" -> 10 x 2 wk | D10: =Releases -> 2 | H10: =PeakTeam -> 18.5 | J10: =AvgTeam -> 9.8194444
B12: ="Average team during report iterations: "&TEXT(AvgDevTeam,"0.0")&" FTE | Contingency "&TEXT(ContPct,"0.0%")&" | Onsite share "&TEXT(OnsiteShare,"0.0%")&" | Cost mode: "&CostMode -> Average team during report iterations: 14.4 FTE | Contingency 18.1% | Onsite share 1.2% | Cost mode: Role mix
B14: Effort and cost by phase | H14: Team and cost by role
B15: Phase | C15: Hours | D15: % of hours | E15: Cost (USD) | F15: Weeks (start-end) | H15: Role | I15: Location | J15: Hours | K15: Rate (USD/h) | L15: Cost (USD)
B16: Initiation & assessment | C16: =INDEX(PhaseHours,1) -> 693 | D16: =IF(TotalBaseHrs>0,C16/TotalBaseHrs,0) -> 0.048378304 | E16: =INDEX(PhaseCost,1) -> 67983.3 | F16: =IF(C16>0,INDEX(PhStart,1)&" - "&INDEX(PhEnd,1),"") -> 1 - 6 | H16: =Cost!B6 -> Delivery manager / PM | I16: =Cost!C6 -> India | J16: =Cost!D6 -> 1440 | K16: =Cost!E6 -> 82 | L16: =Cost!F6 -> 118080
B17: Architecture & design | C17: =INDEX(PhaseHours,2) -> 128 | D17: =IF(TotalBaseHrs>0,C17/TotalBaseHrs,0) -> 0.0089356753 | E17: =INDEX(PhaseCost,2) -> 13510.4 | F17: =IF(C17>0,INDEX(PhStart,2)&" - "&INDEX(PhEnd,2),"") -> 4 - 5 | H17: =Cost!B7 -> Onsite architect | I17: =Cost!C7 -> USA | J17: =Cost!D7 -> 170.6 | K17: =Cost!E7 -> 185 | L17: =Cost!F7 -> 31561
B18: Semantic model build & consolidation | C18: =INDEX(PhaseHours,3) -> 2377.94 | D18: =IF(TotalBaseHrs>0,C18/TotalBaseHrs,0) -> 0.1660039 | E18: =INDEX(PhaseCost,3) -> 147432.28 | F18: =IF(C18>0,INDEX(PhStart,3)&" - "&INDEX(PhEnd,3),"") -> 7 - 18 | H18: =Cost!B8 -> Solution architect | I18: =Cost!C8 -> India | J18: =Cost!D8 -> 259.1 | K18: =Cost!E8 -> 87 | L18: =Cost!F8 -> 22541.7
B19: Report development & unit validation | C19: =INDEX(PhaseHours,4) -> 6206.6629 | D19: =IF(TotalBaseHrs>0,C19/TotalBaseHrs,0) -> 0.43328691 | E19: =INDEX(PhaseCost,4) -> 345090.46 | F19: =IF(C19>0,INDEX(PhStart,4)&" - "&INDEX(PhEnd,4),"") -> 9 - 28 | H19: =Cost!B9 -> BI architect | I19: =Cost!C9 -> India | J19: =Cost!D9 -> 765.891 | K19: =Cost!E9 -> 70 | L19: =Cost!F9 -> 53612.37
B20: SIT & optimization | C20: =INDEX(PhaseHours,5) -> 1840 | D20: =IF(TotalBaseHrs>0,C20/TotalBaseHrs,0) -> 0.12845033 | E20: =INDEX(PhaseCost,5) -> 105340 | F20: =IF(C20>0,INDEX(PhStart,5)&" - "&INDEX(PhEnd,5),"") -> 11 - 31 | H20: =Cost!B10 -> Lead | I20: =Cost!C10 -> India | J20: =Cost!D10 -> 1693.2573 | K20: =Cost!E10 -> 70 | L20: =Cost!F10 -> 118528.01
B21: UAT support | C21: =INDEX(PhaseHours,6) -> 440 | D21: =IF(TotalBaseHrs>0,C21/TotalBaseHrs,0) -> 0.030716384 | E21: =INDEX(PhaseCost,6) -> 25872 | F21: =IF(C21>0,INDEX(PhStart,6)&" - "&INDEX(PhEnd,6),"") -> 13 - 34 | H21: =Cost!B11 -> Sr. engineer | I21: =Cost!C11 -> India | J21: =Cost!D11 -> 3884.1689 | K21: =Cost!E11 -> 62 | L21: =Cost!F11 -> 240818.47
B22: Deployment support | C22: =INDEX(PhaseHours,7) -> 400 | D22: =IF(TotalBaseHrs>0,C22/TotalBaseHrs,0) -> 0.027923985 | E22: =INDEX(PhaseCost,7) -> 25760 | F22: =IF(C22>0,INDEX(PhStart,7)&" - "&INDEX(PhEnd,7),"") -> 13 - 34 | H22: =Cost!B12 -> Engineer | I22: =Cost!C12 -> India | J22: =Cost!D12 -> 4823.5857 | K22: =Cost!E12 -> 50 | L22: =Cost!F12 -> 241179.29
B23: Hypercare | C23: =INDEX(PhaseHours,8) -> 320 | D23: =IF(TotalBaseHrs>0,C23/TotalBaseHrs,0) -> 0.022339188 | E23: =INDEX(PhaseCost,8) -> 19520 | F23: =IF(C23>0,INDEX(PhStart,8)&" - "&INDEX(PhEnd,8),"") -> 27 - 36 | H23: =Cost!B13 -> QA engineer | I23: =Cost!C13 -> India | J23: =Cost!D13 -> 1288 | K23: =Cost!E13 -> 57.5 | L23: =Cost!F13 -> 74060
B24: Security, operations & handover | C24: =INDEX(PhaseHours,9) -> 351 | D24: =IF(TotalBaseHrs>0,C24/TotalBaseHrs,0) -> 0.024503297 | E24: =INDEX(PhaseCost,9) -> 23446.8 | F24: =IF(C24>0,INDEX(PhStart,9)&" - "&INDEX(PhEnd,9),"") -> 9 - 34 | H24: Total | J24: =RoleHrsTotal -> 14324.603 | L24: =RoleCostTotal -> 900380.84
B25: AI readiness | C25: =INDEX(PhaseHours,10) -> 128 | D25: =IF(TotalBaseHrs>0,C25/TotalBaseHrs,0) -> 0.0089356753 | E25: =INDEX(PhaseCost,10) -> 8345.6 | F25: =IF(C25>0,INDEX(PhStart,10)&" - "&INDEX(PhEnd,10),"") -> 9 - 28
B26: Project management | C26: =INDEX(PhaseHours,11) -> 1440 | D26: =IF(TotalBaseHrs>0,C26/TotalBaseHrs,0) -> 0.10052635 | E26: =INDEX(PhaseCost,11) -> 118080 | F26: =IF(C26>0,INDEX(PhStart,11)&" - "&INDEX(PhEnd,11),"") -> 1 - 36
B27: Base effort | C27: =TotalBaseHrs -> 14324.603 | E27: =BaseCost -> 900380.84 | H27: Key dates
B28: Contingency | C28: =ContHrs -> 2596.1602 | E28: =ContCost -> 163183.08 | H28: Milestone | I28: Week | J28: Date
B29: Risk reserve | C29: =RiskHrs -> 90 | E29: =RiskCost -> 5656.9998 | H29: =INDEX(MilestoneLabels,1) -> Assessment sign-off | I29: =INDEX(MilestoneWeeks,1) -> 6 | J29: =INDEX(MilestoneDates,1) -> 46437
B30: Discount | E30: =DiscountAmt -> 0 | H30: =INDEX(MilestoneLabels,2) -> Architecture sign-off | I30: =INDEX(MilestoneWeeks,2) -> 5 | J30: =INDEX(MilestoneDates,2) -> 46430
B31: Pass-throughs | E31: =PassThrough -> 0 | H31: =INDEX(MilestoneLabels,3) -> First semantic models ready | I31: =INDEX(MilestoneWeeks,3) -> 8 | J31: =INDEX(MilestoneDates,3) -> 46451
B32: FIXED PRICE | C32: =TotalHrs -> 17010.763 | E32: =FixedPrice -> 1069220.9 | H32: =INDEX(MilestoneLabels,4) -> First report iteration starts | I32: =INDEX(MilestoneWeeks,4) -> 9 | J32: =INDEX(MilestoneDates,4) -> 46458
H33: =INDEX(MilestoneLabels,5) -> Last report iteration ends | I33: =INDEX(MilestoneWeeks,5) -> 28 | J33: =INDEX(MilestoneDates,5) -> 46598
H34: =INDEX(MilestoneLabels,6) -> Wave 1 go-live | I34: =INDEX(MilestoneWeeks,6) -> 26 | J34: =INDEX(MilestoneDates,6) -> 46584
H35: =INDEX(MilestoneLabels,7) -> Wave 2 go-live | I35: =INDEX(MilestoneWeeks,7) -> 34 | J35: =INDEX(MilestoneDates,7) -> 46640
B36: Effort by migration pair | H36: =INDEX(MilestoneLabels,8) -> Wave 3 go-live | I36: =INDEX(MilestoneWeeks,8) | J36: =INDEX(MilestoneDates,8)
B37: Pair | C37: Source -> target | D37: Reports to build | E37: Hours (incl. shared) | F37: Contingency % | H37: =INDEX(MilestoneLabels,9) -> Wave 4 go-live | I37: =INDEX(MilestoneWeeks,9) | J37: =INDEX(MilestoneDates,9)
B38: =IF(Effort!C7=1,Effort!B7,"") -> Finance OBIEE to Power BI | C38: =IF(Effort!C7=1,Scope!$C7&" -> "&Scope!$D7,"") -> OBIEE -> Power BI | D38: =IF(Effort!C7=1,Effort!R7,"") -> 280 | E38: =IF(Effort!C7=1,Effort!AP7,"") -> 9849.9056 | F38: =IF(Effort!C7=1,Effort!AN7,"") -> 0.15 | H38: =INDEX(MilestoneLabels,10) -> Wave 5 go-live | I38: =INDEX(MilestoneWeeks,10) | J38: =INDEX(MilestoneDates,10)
B39: =IF(Effort!C8=1,Effort!B8,"") -> Sales Tableau to Power BI | C39: =IF(Effort!C8=1,Scope!$C8&" -> "&Scope!$D8,"") -> Tableau -> Power BI | D39: =IF(Effort!C8=1,Effort!R8,"") -> 175 | E39: =IF(Effort!C8=1,Effort!AP8,"") -> 4474.6973 | F39: =IF(Effort!C8=1,Effort!AN8,"") -> 0.25 | H39: =INDEX(MilestoneLabels,11) -> Hypercare exit / programme end | I39: =INDEX(MilestoneWeeks,11) -> 36 | J39: =INDEX(MilestoneDates,11) -> 46654
B40: =IF(Effort!C9=1,Effort!B9,"") | C40: =IF(Effort!C9=1,Scope!$C9&" -> "&Scope!$D9,"") | D40: =IF(Effort!C9=1,Effort!R9,"") | E40: =IF(Effort!C9=1,Effort!AP9,"") | F40: =IF(Effort!C9=1,Effort!AN9,"")
B41: =IF(Effort!C10=1,Effort!B10,"") | C41: =IF(Effort!C10=1,Scope!$C10&" -> "&Scope!$D10,"") | D41: =IF(Effort!C10=1,Effort!R10,"") | E41: =IF(Effort!C10=1,Effort!AP10,"") | F41: =IF(Effort!C10=1,Effort!AN10,"")
B42: =IF(Effort!C11=1,Effort!B11,"") | C42: =IF(Effort!C11=1,Scope!$C11&" -> "&Scope!$D11,"") | D42: =IF(Effort!C11=1,Effort!R11,"") | E42: =IF(Effort!C11=1,Effort!AP11,"") | F42: =IF(Effort!C11=1,Effort!AN11,"")
B43: =IF(Effort!C12=1,Effort!B12,"") | C43: =IF(Effort!C12=1,Scope!$C12&" -> "&Scope!$D12,"") | D43: =IF(Effort!C12=1,Effort!R12,"") | E43: =IF(Effort!C12=1,Effort!AP12,"") | F43: =IF(Effort!C12=1,Effort!AN12,"")
B44: =IF(Effort!C13=1,Effort!B13,"") | C44: =IF(Effort!C13=1,Scope!$C13&" -> "&Scope!$D13,"") | D44: =IF(Effort!C13=1,Effort!R13,"") | E44: =IF(Effort!C13=1,Effort!AP13,"") | F44: =IF(Effort!C13=1,Effort!AN13,"")
B45: =IF(Effort!C14=1,Effort!B14,"") | C45: =IF(Effort!C14=1,Scope!$C14&" -> "&Scope!$D14,"") | D45: =IF(Effort!C14=1,Effort!R14,"") | E45: =IF(Effort!C14=1,Effort!AP14,"") | F45: =IF(Effort!C14=1,Effort!AN14,"")
...

Sheet Setup
A1: Setup
A2: Engagement-wide settings. Yellow cells are inputs; hover a cell for guidance.
B4: Engagement
B5: Client | C5: Example Client
B6: Opportunity | C6: BI modernisation programme
B7: Estimate version | C7: v2.0-draft
B8: Prepared by
B9: Estimate date | C9: 46308
B10: Currency | C10: USD
B11: Planned start date (Monday) | C11: 46391
B13: Delivery parameters
B14: Iteration length (weeks) | C14: 2
B15: Productive hours per person-week | C15: 40
B16: Holiday allowance (stretches calendar dates only) | C16: 0.04
B17: Engagement type | C17: Pure BI
B18: Solve mode | C18: Fix team, compute iterations
B19: Peak report-development team (FTE) - used when fixing team | C19: 10
B20: Development iterations - used when fixing iterations | C20: 8
B21: Ramp-up weeks (report development) | C21: 3
B22: Ramp-down weeks (report development) | C22: 3
B23: Assessment team (FTE) | C23: 3
B24: Architecture team (FTE) | C24: 2
B25: Architecture overlap with assessment | C25: 0.5
B26: Model lead time before report iterations (weeks) | C26: 2
B27: Headcount rounding step (0 = no rounding) | C27: 0.5
B28: PM FTE (pure BI engagements) | C28: 1
B30: SIT, UAT and deployment support (sized per development iteration)
B31: SIT weeks per iteration | C31: 1
B32: SIT minimum engineers | C32: 1
B33: SIT crew sizing (% of dev hours per iteration) | C33: 0.15
B34: SIT fixed hours per iteration (environments, regression) | C34: 8
B35: Final regression cycle (weeks) | C35: 1
B36: UAT support weeks per iteration | C36: 1
B37: UAT engineers when volume <= threshold | C37: 1
B38: UAT engineers when volume > threshold | C38: 2
B39: Volume threshold (report pages per iteration) | C39: 150
B40: Final UAT cycle (weeks) | C40: 1
B41: Deployment support weeks per iteration | C41: 1
B42: Deployment support engineers | C42: 1
B43: Deployment pipeline available? | C43: Yes
...

Sheet Scope
A1: Scope
A2: One row per migration pair (source BI tool + data platform -> target BI tool + data platform). Rows with a source, target and report count are active.
A3: Mixes are fractions that total 100% per row. Retired + Consolidated <= 100%; Derived applies to what remains. Blank automation override = use Setup.
A5: Pair | H5: Report inventory | L5: Report complexity | P5: Rationalisation | S5: Semantic layer | Y5: Security, ops, AI | AC5: Overrides and confidence
A6: # | B6: Pair name | C6: Source BI tool | D6: Target BI tool | E6: Source data platform | F6: Target data platform | G6: Release wave (1-5) | H6: Reports in inventory | I6: Avg pages (sheets) per report | J6: % paginated | K6: % with custom SQL | L6: % Simple | M6: % Medium | N6: % Complex | O6: % Very Complex | P6: % Retired | Q6: % Consolidated | R6: % Derived | S6: Source semantic models / SQL datasets | T6: Model % Simple | U6: Model % Medium | V6: Model % Complex | W6: Model % Very Complex | X6: Target semantic models | Y6: Security model | Z6: Schedules / subscriptions / alerts | AA6: User groups | AB6: AI readiness | AC6: Pair factor override | AD6: Override reason | AE6: Automation override - Assessment | AF6: Automation override - Semantic | AG6: Automation override - Reports | AH6: Input confidence | AI6: Notes
A7: 1 | B7: Finance OBIEE to Power BI | C7: OBIEE | D7: Power BI | E7: Oracle | F7: Snowflake | G7: 1 | H7: 400 | I7: 3 | J7: 0.1 | K7: 0.15 | L7: 0.4 | M7: 0.35 | N7: 0.2 | O7: 0.05 | P7: 0.2 | Q7: 0.1 | R7: 0.1 | S7: 12 | T7: 0.3 | U7: 0.4 | V7: 0.2 | W7: 0.1 | X7: 8 | Y7: Row-level | Z7: 150 | AA7: 20 | AB7: Basic | AH7: Customer inventory | AI7: Example row - replace with real scope
A8: 2 | B8: Sales Tableau to Power BI | C8: Tableau | D8: Power BI | E8: Amazon Redshift | F8: Snowflake | G8: 2 | H8: 250 | I8: 2 | J8: 0 | K8: 0.1 | L8: 0.5 | M8: 0.3 | N8: 0.15 | O8: 0.05 | P8: 0.25 | Q8: 0.05 | R8: 0.1 | S8: 40 | T8: 0.5 | U8: 0.3 | V8: 0.15 | W8: 0.05 | X8: 10 | Y8: Role-based | Z8: 60 | AA8: 10 | AB8: None | AH8: Verbal estimate | AI8: Example row - replace with real scope
A9: 3
A10: 4
A11: 5
A12: 6
A13: 7
A14: 8
A15: 9
A16: 10
A17: 11
A18: 12
A19: 13
A20: 14
... A26: 20

Sheet Risks
A1: Risks
A2: Named risks priced at expected value (impact hours x probability). Example rows - replace with the engagement's risks.
A5: # | B5: Risk | C5: Impact (hours) | D5: Probability | E5: Expected hours | F5: Owner | G5: Mitigation
A6: 1 | B6: Target data platform tables not ready when report iterations start | C6: 200 | D6: 0.3 | E6: =N(C6)*N(D6) -> 60 | F6: Customer | G6: Model-lead gate; mock data for unit tests
A7: 2 | B7: Custom visuals / extensions with no target equivalent | C7: 120 | D7: 0.25 | E7: =N(C7)*N(D7) -> 30 | F7: BI lead | G7: Identify in assessment; agree alternatives
A8: 3 | E8: =N(C8)*N(D8) -> 0
A9: 4 | E9: =N(C9)*N(D9) -> 0
A10: 5 | E10: =N(C10)*N(D10) -> 0
A11: 6 | E11: =N(C11)*N(D11) -> 0
A12: 7 | E12: =N(C12)*N(D12) -> 0
A13: 8 | E13: =N(C13)*N(D13) -> 0
A14: 9 | E14: =N(C14)*N(D14) -> 0
A15: 10 | E15: =N(C15)*N(D15) -> 0
A16: 11 | E16: =N(C16)*N(D16) -> 0
A17: 12 | E17: =N(C17)*N(D17) -> 0
A18: 13 | E18: =N(C18)*N(D18) -> 0
A19: 14 | E19: =N(C19)*N(D19) -> 0
A20: 15 | E20: =N(C20)*N(D20) -> 0
D21: Total | E21: =SUM(E6:E20) -> 90

Sheet Roles
A1: Roles
A2: Plan roles (each priced from one rate-card row) and the share of each phase's hours carried by each role.
A4: Plan roles
A5: # | B5: Plan role | C5: Rate-card key (Role | Grade | Location) | D5: Rate (USD/h) | E5: Location
A6: 1 | B6: Delivery manager / PM | C6: MSE I | G12 | India | D6: =IFERROR(INDEX(RateVals,MATCH(C6,RateKeys,0)),0) -> 82 | E6: =IFERROR(INDEX(RateLocs,MATCH(C6,RateKeys,0)),"") -> India
A7: 2 | B7: Onsite architect | C7: Architect II | G12 | USA | D7: =IFERROR(INDEX(RateVals,MATCH(C7,RateKeys,0)),0) -> 185 | E7: =IFERROR(INDEX(RateLocs,MATCH(C7,RateKeys,0)),"") -> USA
A8: 3 | B8: Solution architect | C8: Sr. Architect I | G13 | India | D8: =IFERROR(INDEX(RateVals,MATCH(C8,RateKeys,0)),0) -> 87 | E8: =IFERROR(INDEX(RateLocs,MATCH(C8,RateKeys,0)),"") -> India
A9: 4 | B9: BI architect | C9: Architect II | G11 | India | D9: =IFERROR(INDEX(RateVals,MATCH(C9,RateKeys,0)),0) -> 70 | E9: =IFERROR(INDEX(RateLocs,MATCH(C9,RateKeys,0)),"") -> India
A10: 5 | B10: Lead | C10: Lead II | G11 | India | D10: =IFERROR(INDEX(RateVals,MATCH(C10,RateKeys,0)),0) -> 70 | E10: =IFERROR(INDEX(RateLocs,MATCH(C10,RateKeys,0)),"") -> India
A11: 6 | B11: Sr. engineer | C11: Sr. Engineer II | G10 | India | D11: =IFERROR(INDEX(RateVals,MATCH(C11,RateKeys,0)),0) -> 62 | E11: =IFERROR(INDEX(RateLocs,MATCH(C11,RateKeys,0)),"") -> India
A12: 7 | B12: Engineer | C12: Engineer II | G8 | India | D12: =IFERROR(INDEX(RateVals,MATCH(C12,RateKeys,0)),0) -> 50 | E12: =IFERROR(INDEX(RateLocs,MATCH(C12,RateKeys,0)),"") -> India
A13: 8 | B13: QA engineer | C13: Sr. Engineer I | G9 | India | D13: =IFERROR(INDEX(RateVals,MATCH(C13,RateKeys,0)),0) -> 57.5 | E13: =IFERROR(INDEX(RateLocs,MATCH(C13,RateKeys,0)),"") -> India
A16: Role mix by phase (share of phase hours; each row must total 100%)
A17: # | B17: Phase | C17: =B6 -> Delivery manager / PM | D17: =B7 -> Onsite architect | E17: =B8 -> Solution architect | F17: =B9 -> BI architect | G17: =B10 -> Lead | H17: =B11 -> Sr. engineer | I17: =B12 -> Engineer | J17: =B13 -> QA engineer | K17: Total
A18: 1 | B18: Initiation & assessment | C18: 0 | D18: 0.2 | E18: 0.3 | F18: 0.3 | G18: 0.2 | H18: 0 | I18: 0 | J18: 0 | K18: =SUM(C18:J18) -> 1
A19: 2 | B19: Architecture & design | C19: 0 | D19: 0.25 | E19: 0.4 | F19: 0.35 | G19: 0 | H19: 0 | I19: 0 | J19: 0 | K19: =SUM(C19:J19) -> 1
A20: 3 | B20: Semantic model build & consolidation | C20: 0 | D20: 0 | E20: 0 | F20: 0.15 | G20: 0.15 | H20: 0.5 | I20: 0.2 | J20: 0 | K20: =SUM(C20:J20) -> 1
A21: 4 | B21: Report development & unit validation | C21: 0 | D21: 0 | E21: 0 | F21: 0 | G21: 0.1 | H21: 0.3 | I21: 0.6 | J21: 0 | K21: =SUM(C21:J21) -> 1
A22: 5 | B22: SIT & optimization | C22: 0 | D22: 0 | E22: 0 | F22: 0 | G22: 0.1 | H22: 0 | I22: 0.2 | J22: 0.7 | K22: =SUM(C22:J22) -> 1
A23: 6 | B23: UAT support | C23: 0 | D23: 0 | E23: 0 | F23: 0 | G23: 0.2 | H23: 0.4 | I23: 0.4 | J23: 0 | K23: =SUM(C23:J23) -> 1
A24: 7 | B24: Deployment support | C24: 0 | D24: 0 | E24: 0 | F24: 0 | G24: 0.3 | H24: 0.7 | I24: 0 | J24: 0 | K24: =SUM(C24:J24) -> 1
A25: 8 | B25: Hypercare | C25: 0 | D25: 0 | E25: 0 | F25: 0 | G25: 0.25 | H25: 0.5 | I25: 0.25 | J25: 0 | K25: =SUM(C25:J25) -> 1
A26: 9 | B26: Security, operations & handover | C26: 0 | D26: 0 | E26: 0 | F26: 0.3 | G26: 0.3 | H26: 0.4 | I26: 0 | J26: 0 | K26: =SUM(C26:J26) -> 1
A27: 10 | B27: AI readiness | C27: 0 | D27: 0 | E27: 0 | F27: 0.4 | G27: 0 | H27: 0.6 | I27: 0 | J27: 0 | K27: =SUM(C27:J27) -> 1
A28: 11 | B28: Project management | C28: 1 | D28: 0 | E28: 0 | F28: 0 | G28: 0 | H28: 0 | I28: 0 | J28: 0 | K28: =SUM(C28:J28) -> 1

Sheet Rates
A1: Rates
A2: Rate card (bill rates, USD per hour) as provided. Key = Role | Grade | Location is what the Roles tab selects.
A4: Role | B4: Grade | C4: Location | D4: Rate (USD/h) | E4: Key | G4: Notes
A5: MSE II | B5: G13 | C5: India | D5: 87 | E5: =IF(A5="","",A5&" | "&B5&" | "&C5) -> MSE II | G13 | India | G5: Source: rate card supplied by the user (bill rates, USD/h). Lead I rows added from the requirements review. MSE = Manager Software Engineer.
A6: MSE I | B6: G12 | C6: India | D6: 82 | E6: =IF(A6="","",A6&" | "&B6&" | "&C6) -> MSE I | G12 | India
A7: Architect II | B7: G12 | C7: India | D7: 70 | E7: =IF(A7="","",A7&" | "&B7&" | "&C7) -> Architect II | G12 | India
A8: Architect I | B8: G11 | C8: India | D8: 65 | E8: =IF(A8="","",A8&" | "&B8&" | "&C8) -> Architect I | G11 | India
A9: Lead II | B9: G11 | C9: India | D9: 70 | E9: =IF(A9="","",A9&" | "&B9&" | "&C9) -> Lead II | G11 | India
A10: Lead II | B10: G10 | C10: India | D10: 70 | E10: =IF(A10="","",A10&" | "&B10&" | "&C10) -> Lead II | G10 | India
A11: Lead I | B11: G10 | C11: India | D11: 62 | E11: =IF(A11="","",A11&" | "&B11&" | "&C11) -> Lead I | G10 | India
A12: Lead I | B12: G9 | C12: India | D12: 62 | E12: =IF(A12="","",A12&" | "&B12&" | "&C12) -> Lead I | G9 | India
A13: Sr. Engineer II | B13: G10 | C13: India | D13: 62 | E13: =IF(A13="","",A13&" | "&B13&" | "&C13) -> Sr. Engineer II | G10 | India
A14: Sr. Engineer II | B14: G9 | C14: India | D14: 62 | E14: =IF(A14="","",A14&" | "&B14&" | "&C14) -> Sr. Engineer II | G9 | India
A15: Sr. Engineer I | B15: G9 | C15: India | D15: 57.5 | E15: =IF(A15="","",A15&" | "&B15&" | "&C15) -> Sr. Engineer I | G9 | India
A16: Sr. Engineer I | B16: G8 | C16: India | D16: 57.5 | E16: =IF(A16="","",A16&" | "&B16&" | "&C16) -> Sr. Engineer I | G8 | India
A17: Engineer II | B17: G8 | C17: India | D17: 50 | E17: =IF(A17="","",A17&" | "&B17&" | "&C17) -> Engineer II | G8 | India
... A28: MSE II | B28: G13 | C28: USA | D28: 210 | E28: =IF(A28="","",A28&" | "&B28&" | "&C28) -> MSE II | G13 | USA
E29: =IF(A29="","",A29&" | "&B29&" | "&C29)
E30: =IF(A30="","",A30&" | "&B30&" | "&C30)
E31: =IF(A31="","",A31&" | "&B31&" | "&C31)
E32: =IF(A32="","",A32&" | "&B32&" | "&C32)
E33: =IF(A33="","",A33&" | "&B33&" | "&C33)
E34: =IF(A34="","",A34&" | "&B34&" | "&C34)
E35: =IF(A35="","",A35&" | "&B35&" | "&C35)
E36: =IF(A36="","",A36&" | "&B36&" | "&C36)
E37: =IF(A37="","",A37&" | "&B37&" | "&C37)
E38: =IF(A38="","",A38&" | "&B38&" | "&C38)

Sheet Lists
A1: Lists
A2: Reference lists behind the drop-downs. BI team maintains; add rows in the blank space - no formula changes needed.
A4: BI tools and archetypes | D4: Archetypes | F4: Pair factor fallback by archetype (source row x target column) - proposal, BI team to confirm | L4: Known pair factors (seeded from old calculator BD7:BD21) | Q4: Data platforms
A5: BI tool | B5: Archetype | D5: Archetype | F5: Source \ Target | G5: Enterprise semantic-layer | H5: Paginated / pixel-perfect | I5: Modern visual / self-service | J5: Modern code-based semantic | L5: Source BI tool | M5: Target BI tool | N5: Factor | O5: Key | Q5: Data platform | S5: YesNo | T5: EngTypes | U5: SolveModes | V5: CostModes | W5: IterLens
A6: SAP BusinessObjects | B6: Enterprise semantic-layer | D6: Enterprise semantic-layer | F6: Enterprise semantic-layer | G6: 1.1 | H6: 1 | I6: 1.1 | J6: 1.2 | L6: OBIEE | M6: Power BI | N6: 1 | O6: =IF(L6="","",L6&"|"&M6) -> OBIEE|Power BI | Q6: Oracle | S6: Yes | T6: Pure BI | U6: Fix team, compute iterations | V6: Role mix | W6: 1
A7: OBIEE | B7: Enterprise semantic-layer | D7: Paginated / pixel-perfect | F7: Paginated / pixel-perfect | G7: 1 | H7: 0.9 | I7: 1.05 | J7: 1.2 | L7: Cognos | M7: Power BI | N7: 1.1 | O7: =IF(L7="","",L7&"|"&M7) -> Cognos|Power BI | Q7: SQL Server | S7: No | T7: Bundled with ETL/EDW programme | U7: Fix iterations, compute team | V7: Blended | W7: 2
A8: Oracle Analytics Server | B8: Enterprise semantic-layer | D8: Modern visual / self-service | F8: Modern visual / self-service | G8: 1.1 | H8: 1 | I8: 0.95 | J8: 1.1 | L8: SAP BusinessObjects | M8: Power BI | N8: 1.25 | O8: =IF(L8="","",L8&"|"&M8) -> SAP BusinessObjects|Power BI | Q8: Teradata
A9: MicroStrategy | B9: Enterprise semantic-layer | D9: Modern code-based semantic | F9: Modern code-based semantic | G9: 1 | H9: 1 | I9: 1 | J9: 1 | L9: Tableau | M9: Power BI | N9: 0.95 | O9: =IF(L9="","",L9&"|"&M9) -> Tableau|Power BI | Q9: Netezza
A10: Cognos | B10: Enterprise semantic-layer | L10: SSRS | M10: Power BI | N10: 1.05 | O10: =IF(L10="","",L10&"|"&M10) -> SSRS|Power BI | Q10: DB2
A11: SSRS | B11: Paginated / pixel-perfect | L11: OBIEE | M11: QuickSight | N11: 1.2 | O11: =IF(L11="","",L11&"|"&M11) -> OBIEE|QuickSight | Q11: SAP HANA
A12: Crystal Reports | B12: Paginated / pixel-perfect | F12: Semantic-model approach by archetype (source row x target column) | L12: Cognos | M12: QuickSight | N12: 1.25 | O12: =IF(L12="","",L12&"|"&M12) -> Cognos|QuickSight | Q12: Snowflake
A13: Tableau | B13: Modern visual / self-service | F13: Source \ Target | G13: Enterprise semantic-layer | H13: Paginated / pixel-perfect | I13: Modern visual / self-service | J13: Modern code-based semantic | L13: Tableau | M13: QuickSight | N13: 1.1 | O13: =IF(L13="","",L13&"|"&M13) -> Tableau|QuickSight | Q13: Databricks
A14: Power BI | B14: Modern visual / self-service | F14: Enterprise semantic-layer | G14: Redesign | H14: Redesign | I14: Redesign | J14: Author (LookML) | L14: SSRS | M14: QuickSight | N14: 1.2 | O14: =IF(L14="","",L14&"|"&M14) -> SSRS|QuickSight | Q14: Google BigQuery
A15: QuickSight | B15: Modern visual / self-service | F15: Paginated / pixel-perfect | G15: Shared datasets | H15: Shared datasets | I15: Shared datasets | J15: Author (LookML) | L15: SAP BusinessObjects | M15: QuickSight | N15: 1.3 | O15: =IF(L15="","",L15&"|"&M15) -> SAP BusinessObjects|QuickSight | Q15: Amazon Redshift
A16: Qlik Sense | B16: Modern visual / self-service | F16: Modern visual / self-service | G16: Redesign | H16: Shared datasets | I16: Translate | J16: Author (LookML) | L16: Cognos | M16: Looker | N16: 1.25 | O16: =IF(L16="","",L16&"|"&M16) -> Cognos|Looker | Q16: Azure Synapse
A17: QlikView | B17: Modern visual / self-service | F17: Modern code-based semantic | G17: Translate | H17: Shared datasets | I17: Translate | J17: Translate | L17: OBIEE | M17: Looker | N17: 1.2 | O17: =IF(L17="","",L17&"|"&M17) -> OBIEE|Looker | Q17: Microsoft Fabric
A18: Looker Studio | B18: Modern visual / self-service | L18: Tableau | M18: Looker | N18: 1.1 | O18: =IF(L18="","",L18&"|"&M18) -> Tableau|Looker | Q18: PostgreSQL
A19: Looker | B19: Modern code-based semantic | L19: SSRS | M19: Looker | N19: 1.2 | O19: =IF(L19="","",L19&"|"&M19) -> SSRS|Looker | Q19: Other
L20: SAP BusinessObjects | M20: Looker | N20: 1.3 | O20: =IF(L20="","",L20&"|"&M20) -> SAP BusinessObjects|Looker
O21: =IF(L21="","",L21&"|"&M21)
O22: =IF(L22="","",L22&"|"&M22)
O23: =IF(L23="","",L23&"|"&M23)
O24: =IF(L24="","",L24&"|"&M24)
O25: =IF(L25="","",L25&"|"&M25)
O26: =IF(L26="","",L26&"|"&M26)
O27: =IF(L27="","",L27&"|"&M27)
O28: =IF(L28="","",L28&"|"&M28)
O29: =IF(L29="","",L29&"|"&M29)
O30: =IF(L30="","",L30&"|"&M30)
O31: =IF(L31="","",L31&"|"&M31)
O32: =IF(L32="","",L32&"|"&M32)
... O45: =IF(L45="","",L45&"|"&M45)

Sheet Baseline
A1: Baseline
A2: Reference values used by the engine. Status shows where each value came from. Change values here only with BI-team sign-off.
A4: Parameter | B4: Value | C4: Unit | D4: Status | E4: Source / note
A6: Report development
A7: Hours per report page - Simple | B7: 3.625 | C7: h / page | D7: Carried | E7: Old calculator F5
A8: Hours per report page - Medium | B8: 6.625 | C8: h / page | D8: Carried | E8: Old calculator F6
A9: Hours per report page - Complex | B9: 9.125 | C9: h / page | D9: Carried | E9: Old calculator F7
A10: Hours per report page - Very Complex | B10: 12.625 | C10: h / page | D10: Carried | E10: Old calculator F8
A11: Hours per derived (similar) report page | B11: 1 | C11: h / page | D11: Carried | E11: Old calculator F9
A12: Learning gain - quarter 1 of iterations | B12: 0 | C12: % saving | D12: Reshaped | E12: User decision 0/10/15/20% (old file 0/15/20/25% by page-tier phase). Applied by quarter of the iteration run.
A13: Learning gain - quarter 2 of iterations | B13: 0.1 | C13: % saving | D13: Reshaped | E13: User decision 0/10/15/20% (old file 0/15/20/25% by page-tier phase). Applied by quarter of the iteration run.
A14: Learning gain - quarter 3 of iterations | B14: 0.15 | C14: % saving | D14: Reshaped | E14: User decision 0/10/15/20% (old file 0/15/20/25% by page-tier phase). Applied by quarter of the iteration run.
A15: Learning gain - quarter 4 of iterations | B15: 0.2 | C15: % saving | D15: Reshaped | E15: User decision 0/10/15/20% (old file 0/15/20/25% by page-tier phase). Applied by quarter of the iteration run.
A16: Average learning gain (effort is spread evenly over iterations) | B16: =AVERAGE(LearnQ) -> 0.1125 | D16: Calculated
A17: Paginated report effort factor | B17: 1.2 | C17: x | D17: New proposal | E17: Paginated / pixel-perfect pages vs interactive pages
A18: Data-platform change uplift on custom-SQL reports | B18: 0.25 | C18: % uplift | D18: New proposal | E18: Applied to the custom-SQL share when source and target data platforms differ
A19: Merge hours per consolidated report | B19: 2 | C19: h / report | D19: New proposal | E19: Effort to fold a consolidated report into the report that absorbs it
A21: Semantic models
A22: Model build hours - Simple | B22: 80 | C22: h / model | D22: New proposal | E22: Replaces old 16/40/80 by reports-per-model (E16); SOP minimum 80 h
A23: Model build hours - Medium | B23: 120 | C23: h / model | D23: New proposal | E23: Replaces old 16/40/80 by reports-per-model (E16); SOP minimum 80 h
A24: Model build hours - Complex | B24: 200 | C24: h / model | D24: New proposal | E24: Replaces old 16/40/80 by reports-per-model (E16); SOP minimum 80 h
A25: Model build hours - Very Complex | B25: 320 | C25: h / model | D25: New proposal | E25: Replaces old 16/40/80 by reports-per-model (E16); SOP minimum 80 h
A26: Consolidation hours per source model merged | B26: 16 | C26: h / model | D26: New proposal | E26: Applied to (source models - target models)
A27: Data-platform change uplift on semantic models | B27: 0.15 | C27: % uplift | D27: New proposal | E27: When source and target data platforms differ
A28: Redesign | B28: 1 | C28: share of build h | D28: New proposal | E28: Semantic-model approach share of full build hours
A29: Translate | B29: 0.4 | C29: share of build h | D29: New proposal | E29: Semantic-model approach share of full build hours
A30: Author (LookML) | B30: 1 | C30: share of build h | D30: New proposal | E30: Semantic-model approach share of full build hours
A31: Shared datasets | B31: 0.3 | C31: share of build h | D31: New proposal | E31: Semantic-model approach share of full build hours
A33: Initiation and assessment (interpolation anchors on inventory pages)
A34: Anchor | B34: Pages | C34: Initiation h | D34: Analysis h | E34: Source
A35: Anchor 1 | B35: 100 | C35: 40 | D35: 80 | E35: Reshaped: old tier values E14/E15 become straight-line anchors (no cliffs)
A36: Anchor 2 | B36: 500 | C36: 60 | D36: 160 | E36: Reshaped: old tier values E14/E15 become straight-line anchors (no cliffs)
A37: Anchor 3 | B37: 1000 | C37: 80 | D37: 240 | E37: Reshaped: old tier values E14/E15 become straight-line anchors (no cliffs)
A38: Anchor 4 | B38: 5000 | C38: 120 | D38: 360 | E38: Reshaped: old tier values E14/E15 become straight-line anchors (no cliffs)
A39: Anchor 5 | B39: 10000 | C39: 160 | D39: 480 | E39: Reshaped: old tier values E14/E15 become straight-line anchors (no cliffs)
A40: Assessment hours per source semantic model | B40: 4 | C40: h / model | D40: New proposal | E40: Inventorying universes / RPD subject areas / packages / SQL datasets
A42: Architecture, security, operations, AI readiness
A43: Architecture hours per distinct target BI tool | B43: 80 | C43: h / tool | D43: New proposal | E43: Tenant/workspace design, security, connectivity, CI/CD, performance, standards
A44: Architecture hours per migration pair | B44: 24 | C44: h / pair | D44: New proposal | E44: Pair-specific design decisions
A45: None | B45: 0 | C45: h / target model | D45: New proposal | E45: Security model build and testing per target semantic model
...

Sheet Effort
A1: Effort
A2: Hours per pair and per phase. Locked - every value is calculated from Scope, Setup and Baseline.
A6: # | B6: Pair | C6: Active | D6: Source archetype | E6: Target archetype | F6: Suggested pair factor | G6: Pair factor used | H6: Semantic approach | I6: Approach share | J6: Data platform change | K6: Report platform uplift | L6: Model platform uplift | M6: Report-type factor | N6: Saving - assessment | O6: Saving - semantic | P6: Saving - reports | Q6: Inventory pages | R6: Reports to build | S6: Derived reports | T6: Full-effort reports | U6: Full-effort pages | V6: Derived pages | W6: Consolidated reports | X6: Mix-weighted h / page | Y6: Report base hours | Z6: Merge hours | AA6: REPORT DEVELOPMENT h | AB6: Target models | AC6: Mix-weighted h / model | AD6: Model build hours | AE6: Consolidation hours | AF6: SEMANTIC MODEL h | AG6: ASSESSMENT (analysis) h | AH6: SECURITY, OPS & HANDOVER h | AI6: AI READINESS h | AJ6: Automation set-up h | AK6: Pair direct hours | AL6: Development hours (semantic + reports) | AM6: Wave | AN6: Contingency % | AO6: Allocated programme hours | AP6: PAIR TOTAL h (before contingency) | AQ6: Contingency h | AR6: Flag: mix not 100% | AS6: Flag: rationalisation > 100% | AT6: Flag: unmapped tool | AU6: Flag: override without reason | AV6: Flag: pages < 1 or no target model
A7: =Scope!$A7 -> 1 | B7: =IF(Scope!$B7="","",Scope!$B7) -> Finance OBIEE to Power BI | C7: =IF(AND(Scope!$C7<>"",Scope!$D7<>"",N(Scope!$H7)>0),1,0) -> 1 | D7: =IF(C7=0,"",IFERROR(INDEX(ToolArch,MATCH(Scope!$C7,ToolNames,0)),"Unmapped")) -> Enterprise semantic-layer | E7: =IF(C7=0,"",IFERROR(INDEX(ToolArch,MATCH(Scope!$D7,ToolNames,0)),"Unmapped")) -> Modern visual / self-service | F7: =IF(C7=0,0,IFERROR(INDEX(KnownFactor,MATCH(Scope!$C7&"|"&Scope!$D7,KnownKey,0)),IFERROR(INDEX(ArchFactor,MATCH(D7,ArchNames,0),MATCH(E7,ArchNames,0)),1))) -> 1 | G7: =IF(C7=0,0,IF(N(Scope!$AC7)>0,MIN(FactorMax,MAX(FactorMin,Scope!$AC7)),F7)) -> 1 | H7: =IF(C7=0,"",IFERROR(INDEX(ApproachMatrix,MATCH(D7,ArchNames,0),MATCH(E7,ArchNames,0)),"Redesign")) -> Redesign | I7: =IF(C7=0,0,IFERROR(INDEX(ApproachShares,MATCH(H7,ApproachNames,0)),1)) -> 1 | J7: =IF(AND(C7=1,Scope!$E7<>"",Scope!$F7<>"",Scope!$E7<>Scope!$F7),1,0) -> 1 | K7: =1+J7*N(Scope!$K7)*DPRepUplift -> 1.0375 | L7: =1+J7*DPModelUplift -> 1.15 | M7: =1+N(Scope!$J7)*(PaginatedFactor-1) -> 1.02 | N7: =IF(Scope!$AE7="",AutoAssess,Scope!$AE7)*CapAssess -> 0 | O7: =IF(Scope!$AF7="",AutoSem,Scope!$AF7)*CapSem -> 0 | P7: =IF(Scope!$AG7="",AutoRep,Scope!$AG7)*CapRep -> 0 | Q7: =C7*N(Scope!$H7)*N(Scope!$I7) -> 1200 | R7: =C7*N(Scope!$H7)*MAX(0,1-N(Scope!$P7)-N(Scope!$Q7)) -> 280 | S7: =R7*N(Scope!$R7) -> 28 | T7: =R7-S7 -> 252 | U7: =T7*N(Scope!$I7) -> 756 | V7: =S7*N(Scope!$I7) -> 84 | W7: =C7*N(Scope!$H7)*N(Scope!$Q7) -> 40 | X7: =N(Scope!$L7)*INDEX(HrsPage,1)+N(Scope!$M7)*INDEX(HrsPage,2)+N(Scope!$N7)*INDEX(HrsPage,3)+N(Scope!$O7)*INDEX(HrsPage,4) -> 6.225 | Y7: =(U7*X7*K7*M7+V7*HrsDerived)*G7 -> 5064.2303 | Z7: =W7*MergeHrs*G7 -> 80 | AA7: =Y7*(1-LearnAvg)*(1-P7)+Z7 -> 4574.5044 | AB7: =C7*N(Scope!$X7) -> 8 | AC7: =N(Scope!$T7)*INDEX(ModelHrs,1)+N(Scope!$U7)*INDEX(ModelHrs,2)+N(Scope!$V7)*INDEX(ModelHrs,3)+N(Scope!$W7)*INDEX(ModelHrs,4) -> 144 | AD7: =AB7*AC7*I7*G7*L7 -> 1324.8 | AE7: =C7*MAX(0,N(Scope!$S7)-N(Scope!$X7))*ConsolHrs*G7 -> 64 | AF7: =(AD7+AE7)*(1-O7) -> 1388.8 | AG7: =IF(C7=0,0,(IF(Q7<=INDEX(AnchorPages,1),INDEX(AnchorAnalysis,1),IF(Q7>=INDEX(AnchorPages,5),INDEX(AnchorAnalysis,5)+(Q7-INDEX(AnchorPages,5))*(INDEX(AnchorAnalysis,5)-INDEX(AnchorAnalysis,4))/(INDEX(AnchorPages,5)-INDEX(AnchorPages,4)),INDEX(AnchorAnalysis,MATCH(Q7,AnchorPages,1))+(Q7-INDEX(AnchorPages,MATCH(Q7,AnchorPages,1)))*(INDEX(AnchorAnalysis,MATCH(Q7,AnchorPages,1)+1)-INDEX(AnchorAnalysis,MATCH(Q7,AnchorPages,1)))/(INDEX(AnchorPages,MATCH(Q7,AnchorPages,1)+1)-INDEX(AnchorPages,MATCH(Q7,AnchorPages,1)))))*G7+N(Scope!$S7)*AssessPerModel)*(1-N7)) -> 294 | AH7: =IF(C7=0,0,AB7*IFERROR(INDEX(SecHrs,MATCH(Scope!$Y7,SecNames,0)),0)+N(Scope!$Z7)*SchedHrs+N(Scope!$AA7)*GroupHrs+HandoverHrs) -> 231 | AI7: =AB7*IFERROR(INDEX(AIHrs,MATCH(Scope!$AB7,AINames,0)),0) -> 128 | AJ7: =IF(AND(C7=1,MAX(N7,O7,P7,AutoSIT,AutoUAT,AutoDep)>0),AutoSetupHrs,0) -> 0 | AK7: =AA7+AF7+AG7+AH7+AI7+AJ7 -> 6616.3044 | AL7: =AA7+AF7 -> 5963.3044 | AM7: =IF(C7=0,0,MIN(5,MAX(1,INT(N(Scope!$G7))))) -> 1 | AN7: =IF(C7=0,0,IFERROR(INDEX(ConfPct,MATCH(Scope!$AH7,ConfNames,0)),MAX(ConfPct))) -> 0.15 | AO7: =IF(SUM($AL$7:$AL$26)>0,AL7/SUM($AL$7:$AL$26)*ProgSharedHrs,0) -> 3233.6012 | AP7: =AK7+AO7 -> 9849.9056 | AQ7: =AP7*AN7 -> 1477.4858 | AR7: =IF(C7=0,0,IF(OR(ABS(N(Scope!$L7)+N(Scope!$M7)+N(Scope!$N7)+N(Scope!$O7)-1)>0.001,AND(N(Scope!$X7)>0,ABS(N(Scope!$T7)+N(Scope!$U7)+N(Scope!$V7)+N(Scope!$W7)-1)>0.001)),1,0)) -> 0 | AS7: =IF(AND(C7=1,N(Scope!$P7)+N(Scope!$Q7)>1),1,0) -> 0 | AT7: =IF(AND(C7=1,OR(D7="Unmapped",E7="Unmapped")),1,0) -> 0 | AU7: =IF(AND(C7=1,N(Scope!$AC7)>0,ROUND(N(Scope!$AC7)-F7,4)<>0,Scope!$AD7=""),1,0) -> 0 | AV7: =IF(AND(C7=1,OR(N(Scope!$I7)<1,N(Scope!$X7)<1)),1,0) -> 0
A8: =Scope!$A8 -> 2 | B8: =IF(Scope!$B8="","",Scope!$B8) -> Sales Tableau to Power BI | C8: =IF(AND(Scope!$C8<>"",Scope!$D8<>"",N(Scope!$H8)>0),1,0) -> 1 | D8: =IF(C8=0,"",IFERROR(INDEX(ToolArch,MATCH(Scope!$C8,ToolNames,0)),"Unmapped")) -> Modern visual / self-service | E8: =IF(C8=0,"",IFERROR(INDEX(ToolArch,MATCH(Scope!$D8,ToolNames,0)),"Unmapped")) -> Modern visual / self-service | F8: =IF(C8=0,0,IFERROR(INDEX(KnownFactor,MATCH(Scope!$C8&"|"&Scope!$D8,KnownKey,0)),IFERROR(INDEX(ArchFactor,MATCH(D8,ArchNames,0),MATCH(E8,ArchNames,0)),1))) -> 0.95 | G8: =IF(C8=0,0,IF(N(Scope!$AC8)>0,MIN(FactorMax,MAX(FactorMin,Scope!$AC8)),F8)) -> 0.95 | H8: =IF(C8=0,"",IFERROR(INDEX(ApproachMatrix,MATCH(D8,ArchNames,0),MATCH(E8,ArchNames,0)),"Redesign")) -> Translate | I8: =IF(C8=0,0,IFERROR(INDEX(ApproachShares,MATCH(H8,ApproachNames,0)),1)) -> 0.4 | J8: =IF(AND(C8=1,Scope!$E8<>"",Scope!$F8<>"",Scope!$E8<>Scope!$F8),1,0) -> 1 | K8: =1+J8*N(Scope!$K8)*DPRepUplift -> 1.025 | L8: =1+J8*DPModelUplift -> 1.15 | M8: =1+N(Scope!$J8)*(PaginatedFactor-1) -> 1 | N8: =IF(Scope!$AE8="",AutoAssess,Scope!$AE8)*CapAssess -> 0 | O8: =IF(Scope!$AF8="",AutoSem,Scope!$AF8)*CapSem -> 0 | P8: =IF(Scope!$AG8="",AutoRep,Scope!$AG8)*CapRep -> 0 | Q8: =C8*N(Scope!$H8)*N(Scope!$I8) -> 500 | R8: =C8*N(Scope!$H8)*MAX(0,1-N(Scope!$P8)-N(Scope!$Q8)) -> 175 | S8: =R8*N(Scope!$R8) -> 17.5 | T8: =R8-S8 -> 157.5 | U8: =T8*N(Scope!$I8) -> 315 | V8: =S8*N(Scope!$I8) -> 35 | W8: =C8*N(Scope!$H8)*N(Scope!$Q8) -> 12.5 | X8: =N(Scope!$L8)*INDEX(HrsPage,1)+N(Scope!$M8)*INDEX(HrsPage,2)+N(Scope!$N8)*INDEX(HrsPage,3)+N(Scope!$O8)*INDEX(HrsPage,4) -> 5.8 | Y8: =(U8*X8*K8*M8+V8*HrsDerived)*G8 -> 1812.2912 | Z8: =W8*MergeHrs*G8 -> 23.75 | AA8: =Y8*(1-LearnAvg)*(1-P8)+Z8 -> 1632.1585 | AB8: =C8*N(Scope!$X8) -> 10 | AC8: =N(Scope!$T8)*INDEX(ModelHrs,1)+N(Scope!$U8)*INDEX(ModelHrs,2)+N(Scope!$V8)*INDEX(ModelHrs,3)+N(Scope!$W8)*INDEX(ModelHrs,4) -> 122 | AD8: =AB8*AC8*I8*G8*L8 -> 533.14 | AE8: =C8*MAX(0,N(Scope!$S8)-N(Scope!$X8))*ConsolHrs*G8 -> 456 | AF8: =(AD8+AE8)*(1-O8) -> 989.14 | AG8: =IF(C8=0,0,(IF(Q8<=INDEX(AnchorPages,1),INDEX(AnchorAnalysis,1),IF(Q8>=INDEX(AnchorPages,5),INDEX(AnchorAnalysis,5)+(Q8-INDEX(AnchorPages,5))*(INDEX(AnchorAnalysis,5)-INDEX(AnchorAnalysis,4))/(INDEX(AnchorPages,5)-INDEX(AnchorPages,4)),INDEX(AnchorAnalysis,MATCH(Q8,AnchorPages,1))+(Q8-INDEX(AnchorPages,MATCH(Q8,AnchorPages,1)))*(INDEX(AnchorAnalysis,MATCH(Q8,AnchorPages,1)+1)-INDEX(AnchorAnalysis,MATCH(Q8,AnchorPages,1)))/(INDEX(AnchorPages,MATCH(Q8,AnchorPages,1)+1)-INDEX(AnchorPages,MATCH(Q8,AnchorPages,1)))))*G8+N(Scope!$S8)*AssessPerModel)*(1-N8)) -> 312 | AH8: =IF(C8=0,0,AB8*IFERROR(INDEX(SecHrs,MATCH(Scope!$Y8,SecNames,0)),0)+N(Scope!$Z8)*SchedHrs+N(Scope!$AA8)*GroupHrs+HandoverHrs) -> 120 | AI8: =AB8*IFERROR(INDEX(AIHrs,MATCH(Scope!$AB8,AINames,0)),0) -> 0 | AJ8: =IF(AND(C8=1,MAX(N8,O8,P8,AutoSIT,AutoUAT,AutoDep)>0),AutoSetupHrs,0) -> 0 | AK8: =AA8+AF8+AG8+AH8+AI8+AJ8 -> 3053.2985 | AL8: =AA8+AF8 -> 2621.2985 | AM8: =IF(C8=0,0,MIN(5,MAX(1,INT(N(Scope!$G8))))) -> 2 | AN8: =IF(C8=0,0,IFERROR(INDEX(ConfPct,MATCH(Scope!$AH8,ConfNames,0)),MAX(ConfPct))) -> 0.25 | AO8: =IF(SUM($AL$7:$AL$26)>0,AL8/SUM($AL$7:$AL$26)*ProgSharedHrs,0) -> 1421.3988 | AP8: =AK8+AO8 -> 4474.6973 | AQ8: =AP8*AN8 -> 1118.6743 | AR8: =IF(C8=0,0,IF(OR(ABS(N(Scope!$L8)+N(Scope!$M8)+N(Scope!$N8)+N(Scope!$O8)-1)>0.001,AND(N(Scope!$X8)>0,ABS(N(Scope!$T8)+N(Scope!$U8)+N(Scope!$V8)+N(Scope!$W8)-1)>0.001)),1,0)) -> 0 | AS8: =IF(AND(C8=1,N(Scope!$P8)+N(Scope!$Q8)>1),1,0) -> 0 | AT8: =IF(AND(C8=1,OR(D8="Unmapped",E8="Unmapped")),1,0) -> 0 | AU8: =IF(AND(C8=1,N(Scope!$AC8)>0,ROUND(N(Scope!$AC8)-F8,4)<>0,Scope!$AD8=""),1,0) -> 0 | AV8: =IF(AND(C8=1,OR(N(Scope!$I8)<1,N(Scope!$X8)<1)),1,0) -> 0
A9: =Scope!$A9 -> 3 | B9: =IF(Scope!$B9="","",Scope!$B9) | C9: =IF(AND(Scope!$C9<>"",Scope!$D9<>"",N(Scope!$H9)>0),1,0) -> 0 | D9: =IF(C9=0,"",IFERROR(INDEX(ToolArch,MATCH(Scope!$C9,ToolNames,0)),"Unmapped")) | E9: =IF(C9=0,"",IFERROR(INDEX(ToolArch,MATCH(Scope!$D9,ToolNames,0)),"Unmapped")) | F9: =IF(C9=0,0,IFERROR(INDEX(KnownFactor,MATCH(Scope!$C9&"|"&Scope!$D9,KnownKey,0)),IFERROR(INDEX(ArchFactor,MATCH(D9,ArchNames,0),MATCH(E9,ArchNames,0)),1))) -> 0 | G9: =IF(C9=0,0,IF(N(Scope!$AC9)>0,MIN(FactorMax,MAX(FactorMin,Scope!$AC9)),F9)) -> 0 | H9: =IF(C9=0,"",IFERROR(INDEX(ApproachMatrix,MATCH(D9,ArchNames,0),MATCH(E9,ArchNames,0)),"Redesign")) | I9: =IF(C9=0,0,IFERROR(INDEX(ApproachShares,MATCH(H9,ApproachNames,0)),1)) -> 0 | J9: =IF(AND(C9=1,Scope!$E9<>"",Scope!$F9<>"",Scope!$E9<>Scope!$F9),1,0) -> 0 | K9: =1+J9*N(Scope!$K9)*DPRepUplift -> 1 | L9: =1+J9*DPModelUplift -> 1 | M9: =1+N(Scope!$J9)*(PaginatedFactor-1) -> 1 | N9: =IF(Scope!$AE9="",AutoAssess,Scope!$AE9)*CapAssess -> 0 | O9: =IF(Scope!$AF9="",AutoSem,Scope!$AF9)*CapSem -> 0 | P9: =IF(Scope!$AG9="",AutoRep,Scope!$AG9)*CapRep -> 0 | Q9: =C9*N(Scope!$H9)*N(Scope!$I9) -> 0 | R9: =C9*N(Scope!$H9)*MAX(0,1-N(Scope!$P9)-N(Scope!$Q9)) -> 0 | S9: =R9*N(Scope!$R9) -> 0 | T9: =R9-S9 -> 0 | U9: =T9*N(Scope!$I9) -> 0 | V9: =S9*N(Scope!$I9) -> 0 | W9: =C9*N(Scope!$H9)*N(Scope!$Q9) -> 0 | X9: =N(Scope!$L9)*INDEX(HrsPage,1)+N(Scope!$M9)*INDEX(HrsPage,2)+N(Scope!$N9)*INDEX(HrsPage,3)+N(Scope!$O9)*INDEX(HrsPage,4) -> 0 | Y9: =(U9*X9*K9*M9+V9*HrsDerived)*G9 -> 0 | Z9: =W9*MergeHrs*G9 -> 0 | AA9: =Y9*(1-LearnAvg)*(1-P9)+Z9 -> 0 | AB9: =C9*N(Scope!$X9) -> 0 | AC9: =N(Scope!$T9)*INDEX(ModelHrs,1)+N(Scope!$U9)*INDEX(ModelHrs,2)+N(Scope!$V9)*INDEX(ModelHrs,3)+N(Scope!$W9)*INDEX(ModelHrs,4) -> 0 | AD9: =AB9*AC9*I9*G9*L9 -> 0 | AE9: =C9*MAX(0,N(Scope!$S9)-N(Scope!$X9))*ConsolHrs*G9 -> 0 | AF9: =(AD9+AE9)*(1-O9) -> 0 | AG9: =IF(C9=0,0,(IF(Q9<=INDEX(AnchorPages,1),INDEX(AnchorAnalysis,1),IF(Q9>=INDEX(AnchorPages,5),INDEX(AnchorAnalysis,5)+(Q9-INDEX(AnchorPages,5))*(INDEX(AnchorAnalysis,5)-INDEX(AnchorAnalysis,4))/(INDEX(AnchorPages,5)-INDEX(AnchorPages,4)),INDEX(AnchorAnalysis,MATCH(Q9,AnchorPages,1))+(Q9-INDEX(AnchorPages,MATCH(Q9,AnchorPages,1)))*(INDEX(AnchorAnalysis,MATCH(Q9,AnchorPages,1)+1)-INDEX(AnchorAnalysis,MATCH(Q9,AnchorPages,1)))/(INDEX(AnchorPages,MATCH(Q9,AnchorPages,1)+1)-INDEX(AnchorPages,MATCH(Q9,AnchorPages,1)))))*G9+N(Scope!$S9)*AssessPerModel)*(1-N9)) -> 0 | AH9: =IF(C9=0,0,AB9*IFERROR(INDEX(SecHrs,MATCH(Scope!$Y9,SecNames,0)),0)+N(Scope!$Z9)*SchedHrs+N(Scope!$AA9)*GroupHrs+HandoverHrs) -> 0 | AI9: =AB9*IFERROR(INDEX(AIHrs,MATCH(Scope!$AB9,AINames,0)),0) -> 0 | AJ9: =IF(AND(C9=1,MAX(N9,O9,P9,AutoSIT,AutoUAT,AutoDep)>0),AutoSetupHrs,0) -> 0 | AK9: =AA9+AF9+AG9+AH9+AI9+AJ9 -> 0 | AL9: =AA9+AF9 -> 0 | AM9: =IF(C9=0,0,MIN(5,MAX(1,INT(N(Scope!$G9))))) -> 0 | AN9: =IF(C9=0,0,IFERROR(INDEX(ConfPct,MATCH(Scope!$AH9,ConfNames,0)),MAX(ConfPct))) -> 0 | AO9: =IF(SUM($AL$7:$AL$26)>0,AL9/SUM($AL$7:$AL$26)*ProgSharedHrs,0) -> 0 | AP9: =AK9+AO9 -> 0 | AQ9: =AP9*AN9 -> 0 | AR9: =IF(C9=0,0,IF(OR(ABS(N(Scope!$L9)+N(Scope!$M9)+N(Scope!$N9)+N(Scope!$O9)-1)>0.001,AND(N(Scope!$X9)>0,ABS(N(Scope!$T9)+N(Scope!$U9)+N(Scope!$V9)+N(Scope!$W9)-1)>0.001)),1,0)) -> 0 | AS9: =IF(AND(C9=1,N(Scope!$P9)+N(Scope!$Q9)>1),1,0) -> 0 | AT9: =IF(AND(C9=1,OR(D9="Unmapped",E9="Unmapped")),1,0) -> 0 | AU9: =IF(AND(C9=1,N(Scope!$AC9)>0,ROUND(N(Scope!$AC9)-F9,4)<>0,Scope!$AD9=""),1,0) -> 0 | AV9: =IF(AND(C9=1,OR(N(Scope!$I9)<1,N(Scope!$X9)<1)),1,0) -> 0
A10: =Scope!$A10 -> 4 | B10: =IF(Scope!$B10="","",Scope!$B10) | C10: =IF(AND(Scope!$C10<>"",Scope!$D10<>"",N(Scope!$H10)>0),1,0) -> 0 | D10: =IF(C10=0,"",IFERROR(INDEX(ToolArch,MATCH(Scope!$C10,ToolNames,0)),"Unmapped")) | E10: =IF(C10=0,"",IFERROR(INDEX(ToolArch,MATCH(Scope!$D10,ToolNames,0)),"Unmapped")) | F10: =IF(C10=0,0,IFERROR(INDEX(KnownFactor,MATCH(Scope!$C10&"|"&Scope!$D10,KnownKey,0)),IFERROR(INDEX(ArchFactor,MATCH(D10,ArchNames,0),MATCH(E10,ArchNames,0)),1))) -> 0 | G10: =IF(C10=0,0,IF(N(Scope!$AC10)>0,MIN(FactorMax,MAX(FactorMin,Scope!$AC10)),F10)) -> 0 | H10: =IF(C10=0,"",IFERROR(INDEX(ApproachMatrix,MATCH(D10,ArchNames,0),MATCH(E10,ArchNames,0)),"Redesign")) | I10: =IF(C10=0,0,IFERROR(INDEX(ApproachShares,MATCH(H10,ApproachNames,0)),1)) -> 0 | J10: =IF(AND(C10=1,Scope!$E10<>"",Scope!$F10<>"",Scope!$E10<>Scope!$F10),1,0) -> 0 | K10: =1+J10*N(Scope!$K10)*DPRepUplift -> 1 | L10: =1+J10*DPModelUplift -> 1 | M10: =1+N(Scope!$J10)*(PaginatedFactor-1) -> 1 | N10: =IF(Scope!$AE10="",AutoAssess,Scope!$AE10)*CapAssess -> 0 | O10: =IF(Scope!$AF10="",AutoSem,Scope!$AF10)*CapSem -> 0 | P10: =IF(Scope!$AG10="",AutoRep,Scope!$AG10)*CapRep -> 0 | Q10: =C10*N(Scope!$H10)*N(Scope!$I10) -> 0 | R10: =C10*N(Scope!$H10)*MAX(0,1-N(Scope!$P10)-N(Scope!$Q10)) -> 0 | S10: =R10*N(Scope!$R10) -> 0 | T10: =R10-S10 -> 0 | U10: =T10*N(Scope!$I10) -> 0 | V10: =S10*N(Scope!$I10) -> 0 | W10: =C10*N(Scope!$H10)*N(Scope!$Q10) -> 0 | X10: =N(Scope!$L10)*INDEX(HrsPage,1)+N(Scope!$M10)*INDEX(HrsPage,2)+N(Scope!$N10)*INDEX(HrsPage,3)+N(Scope!$O10)*INDEX(HrsPage,4) -> 0 | Y10: =(U10*X10*K10*M10+V10*HrsDerived)*G10 -> 0 | Z10: =W10*MergeHrs*G10 -> 0 | AA10: =Y10*(1-LearnAvg)*(1-P10)+Z10 -> 0 | AB10: =C10*N(Scope!$X10) -> 0 | AC10: =N(Scope!$T10)*INDEX(ModelHrs,1)+N(Scope!$U10)*INDEX(ModelHrs,2)+N(Scope!$V10)*INDEX(ModelHrs,3)+N(Scope!$W10)*INDEX(ModelHrs,4) -> 0 | AD10: =AB10*AC10*I10*G10*L10 -> 0 | AE10: =C10*MAX(0,N(Scope!$S10)-N(Scope!$X10))*ConsolHrs*G10 -> 0 | AF10: =(AD10+AE10)*(1-O10) -> 0 | AG10: =IF(C10=0,0,(IF(Q10<=INDEX(AnchorPages,1),INDEX(AnchorAnalysis,1),IF(Q10>=INDEX(AnchorPages,5),INDEX(AnchorAnalysis,5)+(Q10-INDEX(AnchorPages,5))*(INDEX(AnchorAnalysis,5)-INDEX(AnchorAnalysis,4))/(INDEX(AnchorPages,5)-INDEX(AnchorPages,4)),INDEX(AnchorAnalysis,MATCH(Q10,AnchorPages,1))+(Q10-INDEX(AnchorPages,MATCH(Q10,AnchorPages,1)))*(INDEX(AnchorAnalysis,MATCH(Q10,AnchorPages,1)+1)-INDEX(AnchorAnalysis,MATCH(Q10,AnchorPages,1)))/(INDEX(AnchorPages,MATCH(Q10,AnchorPages,1)+1)-INDEX(AnchorPages,MATCH(Q10,AnchorPages,1)))))*G10+N(Scope!$S10)*AssessPerModel)*(1-N10)) -> 0 | AH10: =IF(C10=0,0,AB10*IFERROR(INDEX(SecHrs,MATCH(Scope!$Y10,SecNames,0)),0)+N(Scope!$Z10)*SchedHrs+N(Scope!$AA10)*GroupHrs+HandoverHrs) -> 0 | AI10: =AB10*IFERROR(INDEX(AIHrs,MATCH(Scope!$AB10,AINames,0)),0) -> 0 | AJ10: =IF(AND(C10=1,MAX(N10,O10,P10,AutoSIT,AutoUAT,AutoDep)>0),AutoSetupHrs,0) -> 0 | AK10: =AA10+AF10+AG10+AH10+AI10+AJ10 -> 0 | AL10: =AA10+AF10 -> 0 | AM10: =IF(C10=0,0,MIN(5,MAX(1,INT(N(Scope!$G10))))) -> 0 | AN10: =IF(C10=0,0,IFERROR(INDEX(ConfPct,MATCH(Scope!$AH10,ConfNames,0)),MAX(ConfPct))) -> 0 | AO10: =IF(SUM($AL$7:$AL$26)>0,AL10/SUM($AL$7:$AL$26)*ProgSharedHrs,0) -> 0 | AP10: =AK10+AO10 -> 0 | AQ10: =AP10*AN10 -> 0 | AR10: =IF(C10=0,0,IF(OR(ABS(N(Scope!$L10)+N(Scope!$M10)+N(Scope!$N10)+N(Scope!$O10)-1)>0.001,AND(N(Scope!$X10)>0,ABS(N(Scope!$T10)+N(Scope!$U10)+N(Scope!$V10)+N(Scope!$W10)-1)>0.001)),1,0)) -> 0 | AS10: =IF(AND(C10=1,N(Scope!$P10)+N(Scope!$Q10)>1),1,0) -> 0 | AT10: =IF(AND(C10=1,OR(D10="Unmapped",E10="Unmapped")),1,0) -> 0 | AU10: =IF(AND(C10=1,N(Scope!$AC10)>0,ROUND(N(Scope!$AC10)-F10,4)<>0,Scope!$AD10=""),1,0) -> 0 | AV10: =IF(AND(C10=1,OR(N(Scope!$I10)<1,N(Scope!$X10)<1)),1,0) -> 0
A11: =Scope!$A11 -> 5 | B11: =IF(Scope!$B11="","",Scope!$B11) | C11: =IF(AND(Scope!$C11<>"",Scope!$D11<>"",N(Scope!$H11)>0),1,0) -> 0 | D11: =IF(C11=0,"",IFERROR(INDEX(ToolArch,MATCH(Scope!$C11,ToolNames,0)),"Unmapped")) | E11: =IF(C11=0,"",IFERROR(INDEX(ToolArch,MATCH(Scope!$D11,ToolNames,0)),"Unmapped")) | F11: =IF(C11=0,0,IFERROR(INDEX(KnownFactor,MATCH(Scope!$C11&"|"&Scope!$D11,KnownKey,0)),IFERROR(INDEX(ArchFactor,MATCH(D11,ArchNames,0),MATCH(E11,ArchNames,0)),1))) -> 0 | G11: =IF(C11=0,0,IF(N(Scope!$AC11)>0,MIN(FactorMax,MAX(FactorMin,Scope!$AC11)),F11)) -> 0 | H11: =IF(C11=0,"",IFERROR(INDEX(ApproachMatrix,MATCH(D11,ArchNames,0),MATCH(E11,ArchNames,0)),"Redesign")) | I11: =IF(C11=0,0,IFERROR(INDEX(ApproachShares,MATCH(H11,ApproachNames,0)),1)) -> 0 | J11: =IF(AND(C11=1,Scope!$E11<>"",Scope!$F11<>"",Scope!$E11<>Scope!$F11),1,0) -> 0 | K11: =1+J11*N(Scope!$K11)*DPRepUplift -> 1 | L11: =1+J11*DPModelUplift -> 1 | M11: =1+N(Scope!$J11)*(PaginatedFactor-1) -> 1 | N11: =IF(Scope!$AE11="",AutoAssess,Scope!$AE11)*CapAssess -> 0 | O11: =IF(Scope!$AF11="",AutoSem,Scope!$AF11)*CapSem -> 0 | P11: =IF(Scope!$AG11="",AutoRep,Scope!$AG11)*CapRep -> 0 | Q11: =C11*N(Scope!$H11)*N(Scope!$I11) -> 0 | R11: =C11*N(Scope!$H11)*MAX(0,1-N(Scope!$P11)-N(Scope!$Q11)) -> 0 | S11: =R11*N(Scope!$R11) -> 0 | T11: =R11-S11 -> 0 | U11: =T11*N(Scope!$I11) -> 0 | V11: =S11*N(Scope!$I11) -> 0 | W11: =C11*N(Scope!$H11)*N(Scope!$Q11) -> 0 | X11: =N(Scope!$L11)*INDEX(HrsPage,1)+N(Scope!$M11)*INDEX(HrsPage,2)+N(Scope!$N11)*INDEX(HrsPage,3)+N(Scope!$O11)*INDEX(HrsPage,4) -> 0 | Y11: =(U11*X11*K11*M11+V11*HrsDerived)*G11 -> 0 | Z11: =W11*MergeHrs*G11 -> 0 | AA11: =Y11*(1-LearnAvg)*(1-P11)+Z11 -> 0 | AB11: =C11*N(Scope!$X11) -> 0 | AC11: =N(Scope!$T11)*INDEX(ModelHrs,1)+N(Scope!$U11)*INDEX(ModelHrs,2)+N(Scope!$V11)*INDEX(ModelHrs,3)+N(Scope!$W11)*INDEX(ModelHrs,4) -> 0 | AD11: =AB11*AC11*I11*G11*L11 -> 0 | AE11: =C11*MAX(0,N(Scope!$S11)-N(Scope!$X11))*ConsolHrs*G11 -> 0 | AF11: =(AD11+AE11)*(1-O11) -> 0 | AG11: =IF(C11=0,0,(IF(Q11<=INDEX(AnchorPages,1),INDEX(AnchorAnalysis,1),IF(Q11>=INDEX(AnchorPages,5),INDEX(AnchorAnalysis,5)+(Q11-INDEX(AnchorPages,5))*(INDEX(AnchorAnalysis,5)-INDEX(AnchorAnalysis,4))/(INDEX(AnchorPages,5)-INDEX(AnchorPages,4)),INDEX(AnchorAnalysis,MATCH(Q11,AnchorPages,1))+(Q11-INDEX(AnchorPages,MATCH(Q11,AnchorPages,1)))*(INDEX(AnchorAnalysis,MATCH(Q11,AnchorPages,1)+1)-INDEX(AnchorAnalysis,MATCH(Q11,AnchorPages,1)))/(INDEX(AnchorPages,MATCH(Q11,AnchorPages,1)+1)-INDEX(AnchorPages,MATCH(Q11,AnchorPages,1)))))*G11+N(Scope!$S11)*AssessPerModel)*(1-N11)) -> 0 | AH11: =IF(C11=0,0,AB11*IFERROR(INDEX(SecHrs,MATCH(Scope!$Y11,SecNames,0)),0)+N(Scope!$Z11)*SchedHrs+N(Scope!$AA11)*GroupHrs+HandoverHrs) -> 0 | AI11: =AB11*IFERROR(INDEX(AIHrs,MATCH(Scope!$AB11,AINames,0)),0) -> 0 | AJ11: =IF(AND(C11=1,MAX(N11,O11,P11,AutoSIT,AutoUAT,AutoDep)>0),AutoSetupHrs,0) -> 0 | AK11: =AA11+AF11+AG11+AH11+AI11+AJ11 -> 0 | AL11: =AA11+AF11 -> 0 | AM11: =IF(C11=0,0,MIN(5,MAX(1,INT(N(Scope!$G11))))) -> 0 | AN11: =IF(C11=0,0,IFERROR(INDEX(ConfPct,MATCH(Scope!$AH11,ConfNames,0)),MAX(ConfPct))) -> 0 | AO11: =IF(SUM($AL$7:$AL$26)>0,AL11/SUM($AL$7:$AL$26)*ProgSharedHrs,0) -> 0 | AP11: =AK11+AO11 -> 0 | AQ11: =AP11*AN11 -> 0 | AR11: =IF(C11=0,0,IF(OR(ABS(N(Scope!$L11)+N(Scope!$M11)+N(Scope!$N11)+N(Scope!$O11)-1)>0.001,AND(N(Scope!$X11)>0,ABS(N(Scope!$T11)+N(Scope!$U11)+N(Scope!$V11)+N(Scope!$W11)-1)>0.001)),1,0)) -> 0 | AS11: =IF(AND(C11=1,N(Scope!$P11)+N(Scope!$Q11)>1),1,0) -> 0 | AT11: =IF(AND(C11=1,OR(D11="Unmapped",E11="Unmapped")),1,0) -> 0 | AU11: =IF(AND(C11=1,N(Scope!$AC11)>0,ROUND(N(Scope!$AC11)-F11,4)<>0,Scope!$AD11=""),1,0) -> 0 | AV11: =IF(AND(C11=1,OR(N(Scope!$I11)<1,N(Scope!$X11)<1)),1,0) -> 0
A12: =Scope!$A12 -> 6 | B12: =IF(Scope!$B12="","",Scope!$B12) | C12: =IF(AND(Scope!$C12<>"",Scope!$D12<>"",N(Scope!$H12)>0),1,0) -> 0 | D12: =IF(C12=0,"",IFERROR(INDEX(ToolArch,MATCH(Scope!$C12,ToolNames,0)),"Unmapped")) | E12: =IF(C12=0,"",IFERROR(INDEX(ToolArch,MATCH(Scope!$D12,ToolNames,0)),"Unmapped")) | F12: =IF(C12=0,0,IFERROR(INDEX(KnownFactor,MATCH(Scope!$C12&"|"&Scope!$D12,KnownKey,0)),IFERROR(INDEX(ArchFactor,MATCH(D12,ArchNames,0),MATCH(E12,ArchNames,0)),1))) -> 0 | G12: =IF(C12=0,0,IF(N(Scope!$AC12)>0,MIN(FactorMax,MAX(FactorMin,Scope!$AC12)),F12)) -> 0 | H12: =IF(C12=0,"",IFERROR(INDEX(ApproachMatrix,MATCH(D12,ArchNames,0),MATCH(E12,ArchNames,0)),"Redesign")) | I12: =IF(C12=0,0,IFERROR(INDEX(ApproachShares,MATCH(H12,ApproachNames,0)),1)) -> 0 | J12: =IF(AND(C12=1,Scope!$E12<>"",Scope!$F12<>"",Scope!$E12<>Scope!$F12),1,0) -> 0 | K12: =1+J12*N(Scope!$K12)*DPRepUplift -> 1 | L12: =1+J12*DPModelUplift -> 1 | M12: =1+N(Scope!$J12)*(PaginatedFactor-1) -> 1 | N12: =IF(Scope!$AE12="",AutoAssess,Scope!$AE12)*CapAssess -> 0 | O12: =IF(Scope!$AF12="",AutoSem,Scope!$AF12)*CapSem -> 0 | P12: =IF(Scope!$AG12="",AutoRep,Scope!$AG12)*CapRep -> 0 | Q12: =C12*N(Scope!$H12)*N(Scope!$I12) -> 0 | R12: =C12*N(Scope!$H12)*MAX(0,1-N(Scope!$P12)-N(Scope!$Q12)) -> 0 | S12: =R12*N(Scope!$R12) -> 0 | T12: =R12-S12 -> 0 | U12: =T12*N(Scope!$I12) -> 0 | V12: =S12*N(Scope!$I12) -> 0 | W12: =C12*N(Scope!$H12)*N(Scope!$Q12) -> 0 | X12: =N(Scope!$L12)*INDEX(HrsPage,1)+N(Scope!$M12)*INDEX(HrsPage,2)+N(Scope!$N12)*INDEX(HrsPage,3)+N(Scope!$O12)*INDEX(HrsPage,4) -> 0 | Y12: =(U12*X12*K12*M12+V12*HrsDerived)*G12 -> 0 | Z12: =W12*MergeHrs*G12 -> 0 | AA12: =Y12*(1-LearnAvg)*(1-P12)+Z12 -> 0 | AB12: =C12*N(Scope!$X12) -> 0 | AC12: =N(Scope!$T12)*INDEX(ModelHrs,1)+N(Scope!$U12)*INDEX(ModelHrs,2)+N(Scope!$V12)*INDEX(ModelHrs,3)+N(Scope!$W12)*INDEX(ModelHrs,4) -> 0 | AD12: =AB12*AC12*I12*G12*L12 -> 0 | AE12: =C12*MAX(0,N(Scope!$S12)-N(Scope!$X12))*ConsolHrs*G12 -> 0 | AF12: =(AD12+AE12)*(1-O12) -> 0 | AG12: =IF(C12=0,0,(IF(Q12<=INDEX(AnchorPages,1),INDEX(AnchorAnalysis,1),IF(Q12>=INDEX(AnchorPages,5),INDEX(AnchorAnalysis,5)+(Q12-INDEX(AnchorPages,5))*(INDEX(AnchorAnalysis,5)-INDEX(AnchorAnalysis,4))/(INDEX(AnchorPages,5)-INDEX(AnchorPages,4)),INDEX(AnchorAnalysis,MATCH(Q12,AnchorPages,1))+(Q12-INDEX(AnchorPages,MATCH(Q12,AnchorPages,1)))*(INDEX(AnchorAnalysis,MATCH(Q12,AnchorPages,1)+1)-INDEX(AnchorAnalysis,MATCH(Q12,AnchorPages,1)))/(INDEX(AnchorPages,MATCH(Q12,AnchorPages,1)+1)-INDEX(AnchorPages,MATCH(Q12,AnchorPages,1)))))*G12+N(Scope!$S12)*AssessPerModel)*(1-N12)) -> 0 | AH12: =IF(C12=0,0,AB12*IFERROR(INDEX(SecHrs,MATCH(Scope!$Y12,SecNames,0)),0)+N(Scope!$Z12)*SchedHrs+N(Scope!$AA12)*GroupHrs+HandoverHrs) -> 0 | AI12: =AB12*IFERROR(INDEX(AIHrs,MATCH(Scope!$AB12,AINames,0)),0) -> 0 | AJ12: =IF(AND(C12=1,MAX(N12,O12,P12,AutoSIT,AutoUAT,AutoDep)>0),AutoSetupHrs,0) -> 0 | AK12: =AA12+AF12+AG12+AH12+AI12+AJ12 -> 0 | AL12: =AA12+AF12 -> 0 | AM12: =IF(C12=0,0,MIN(5,MAX(1,INT(N(Scope!$G12))))) -> 0 | AN12: =IF(C12=0,0,IFERROR(INDEX(ConfPct,MATCH(Scope!$AH12,ConfNames,0)),MAX(ConfPct))) -> 0 | AO12: =IF(SUM($AL$7:$AL$26)>0,AL12/SUM($AL$7:$AL$26)*ProgSharedHrs,0) -> 0 | AP12: =AK12+AO12 -> 0 | AQ12: =AP12*AN12 -> 0 | AR12: =IF(C12=0,0,IF(OR(ABS(N(Scope!$L12)+N(Scope!$M12)+N(Scope!$N12)+N(Scope!$O12)-1)>0.001,AND(N(Scope!$X12)>0,ABS(N(Scope!$T12)+N(Scope!$U12)+N(Scope!$V12)+N(Scope!$W12)-1)>0.001)),1,0)) -> 0 | AS12: =IF(AND(C12=1,N(Scope!$P12)+N(Scope!$Q12)>1),1,0) -> 0 | AT12: =IF(AND(C12=1,OR(D12="Unmapped",E12="Unmapped")),1,0) -> 0 | AU12: =IF(AND(C12=1,N(Scope!$AC12)>0,ROUND(N(Scope!$AC12)-F12,4)<>0,Scope!$AD12=""),1,0) -> 0 | AV12: =IF(AND(C12=1,OR(N(Scope!$I12)<1,N(Scope!$X12)<1)),1,0) -> 0
